Workbook

Sheet Sheet1
A1: periode_data | B1: tanggal | C1: pm_10 | D1: pm_duakomalima | E1: so2 | F1: co | G1: o3 | H1: no2 | I1: max | J1: critical | K1: categori | L1: lokasi_spku | N1: U1 | O1: U2 | P1: U1^2 | Q1: U2^2 | R1: Jarak D1 | S1: Jarak D2 | T1: F.Objektif | V1: (u1)^m | W1: (u2)^m | X1: (u1)^m.X | Y1: (u2)^m.X | Z1: d1^2 | AA1: d2^2 | AB1: u1 Baru | AC1: u2 Baru | AE1: Label | AF1: ce kecocokan
A2: 202212 | B2: 44926.625 | C2: 54 | D2: 73 | E2: 56 | F2: 24 | G2: 23 | H2: 24 | I2: 73 | J2: PM2,5 | K2: SEDANG | L2: DKI4 | N2: =(C2 - MIN(C$2:C$99)) / (MAX(C$2:C$99) - MIN(C$2:C$99)) -> 0.46551724 | O2: =(D2-MIN(D$2:D$99))/(MAX(D$2:D$99)-MIN(D$2:D$99)) -> 0.28571429 | P2: =(E2-MIN(E$2:E$99))/(MAX(E$2:E$99)-MIN(E$2:E$99)) -> 0.91666667 | Q2: =(F2-MIN(F$2:F$99))/(MAX(F$2:F$99)-MIN(F$2:F$99)) -> 0.78947368 | R2: =(G2-MIN(G$2:G$99))/(MAX(G$2:G$99)-MIN(G$2:G$99)) -> 0.036585366 | S2: =(H2-MIN(H$2:H$99))/(MAX(H$2:H$99)-MIN(H$2:H$99)) -> 0.34375 | T2: =SUM(N2:S2) -> 2.8377072 | V2: 0.1 | W2: =1-V2 -> 0.9 | X2: =V2^2 * N2 -> 0.0046551724 | Y2: =W2^2 * N2 -> 0.37706897 | Z2: =(N2-N$102)^2+(O2-O$102)^2+(P2-P$102)^2+(Q2-Q$102)^2+(R2-R$102)^2+(S2-S$102)^2 -> 0.41615543 | AA2: =(N2-$N$103)^2 + (O2-$O$103)^2 + (P2-$P$103)^2 + (Q2-$Q$103)^2 + (R2-$R$103)^2 + (S2-$S$103)^2 -> 0.52287379 | AB2: =(1/Z2) / ((1/Z2) + (1/AA2)) -> 0.55682377 | AC2: =1 - AB2 -> 0.44317623 | AE2: =IF(AB2 > AC2, 1, 2) -> 1 | AF2: =((VALUE(IF(OR(AND(AE2=2, K2="SEDANG"), AND(AE2=1, K2="TIDAK SEHAT")), 1, 0)))*1)*1 -> 0
A3: 202212 | B3: 44925 | C3: 40 | D3: 64 | E3: 57 | F3: 21 | G3: 17 | H3: 24 | I3: 64 | J3: PM2,5 | K3: SEDANG | L3: DKI4 | N3: =(C3 - MIN(C$2:C$99)) / (MAX(C$2:C$99) - MIN(C$2:C$99)) -> 0.22413793 | O3: =(D3-MIN(D$2:D$99))/(MAX(D$2:D$99)-MIN(D$2:D$99)) -> 0.2 | P3: =(E3-MIN(E$2:E$99))/(MAX(E$2:E$99)-MIN(E$2:E$99)) -> 1 | Q3: =(F3-MIN(F$2:F$99))/(MAX(F$2:F$99)-MIN(F$2:F$99)) -> 0.63157895 | R3: =(G3-MIN(G$2:G$99))/(MAX(G$2:G$99)-MIN(G$2:G$99)) -> 0 | S3: =(H3-MIN(H$2:H$99))/(MAX(H$2:H$99)-MIN(H$2:H$99)) -> 0.34375 | T3: =SUM(N3:S3) -> 2.3994669 | V3: 0.2 | W3: =1-V3 -> 0.8 | X3: =V3^2 * N3 -> 0.0089655172 | Y3: =W3^2 * N3 -> 0.14344828 | Z3: =(N3-$N$102)^2 + (O3-$O$102)^2 + (P3-$P$102)^2 + (Q3-$Q$102)^2 + (R3-$R$102)^2 + (S3-$S$102)^2 -> 0.58184843 | AA3: =(N3-$N$103)^2+(O3-$O$103)^2+(P3-$P$103)^2+(Q3-$Q$103)^2+(R3-$R$103)^2+(S3-$S$103)^2 -> 0.73284298 | AB3: =(1/Z3) / ((1/Z3) + (1/AA3)) -> 0.55742585 | AC3: =1 - AB3 -> 0.44257415 | AE3: =IF(AB3 > AC3, 1, 2) -> 1 | AF3: =((VALUE(IF(OR(AND(AE3=2, K3="SEDANG"), AND(AE3=1, K3="TIDAK SEHAT")), 1, 0)))*1)*1 -> 0
A4: 202207 | B4: 44748 | C4: 75 | D4: 129 | E4: 45 | F4: 25 | G4: 71 | H4: 26 | I4: 129 | J4: PM2,5 | K4: TIDAK SEHAT | L4: DKI4 | N4: =(C4 - MIN(C$2:C$99)) / (MAX(C$2:C$99) - MIN(C$2:C$99)) -> 0.82758621 | O4: =(D4-MIN(D$2:D$99))/(MAX(D$2:D$99)-MIN(D$2:D$99)) -> 0.81904762 | P4: =(E4-MIN(E$2:E$99))/(MAX(E$2:E$99)-MIN(E$2:E$99)) -> 0 | Q4: =(F4-MIN(F$2:F$99))/(MAX(F$2:F$99)-MIN(F$2:F$99)) -> 0.84210526 | R4: =(G4-MIN(G$2:G$99))/(MAX(G$2:G$99)-MIN(G$2:G$99)) -> 0.32926829 | S4: =(H4-MIN(H$2:H$99))/(MAX(H$2:H$99)-MIN(H$2:H$99)) -> 0.40625 | T4: =SUM(N4:S4) -> 3.2242574 | V4: 0.3 | W4: =1-V4 -> 0.7 | X4: =V4^2 * N4 -> 0.074482759 | Y4: =W4^2 * N4 -> 0.40551724 | Z4: =(N4-$N$102)^2 + (O4-$O$102)^2 + (P4-$P$102)^2 + (Q4-$Q$102)^2 + (R4-$R$102)^2 + (S4-$S$102)^2 -> 0.59682758 | AA4: =(N4-$N$103)^2+(O4-$O$103)^2+(P4-$P$103)^2+(Q4-$Q$103)^2+(R4-$R$103)^2+(S4-$S$103)^2 -> 0.48451188 | AB4: =(1/Z4) / ((1/Z4) + (1/AA4)) -> 0.4480664 | AC4: =1 - AB4 -> 0.5519336 | AE4: =IF(AB4 > AC4, 1, 2) -> 2 | AF4: =((VALUE(IF(OR(AND(AE4=2, K4="SEDANG"), AND(AE4=1, K4="TIDAK SEHAT")), 1, 0)))*1)*1 -> 0
A5: 202207 | B5: 44747 | C5: 66 | D5: 110 | E5: 47 | F5: 16 | G5: 61 | H5: 23 | I5: 110 | J5: PM2,5 | K5: TIDAK SEHAT | L5: DKI4 | N5: =(C5 - MIN(C$2:C$99)) / (MAX(C$2:C$99) - MIN(C$2:C$99)) -> 0.67241379 | O5: =(D5-MIN(D$2:D$99))/(MAX(D$2:D$99)-MIN(D$2:D$99)) -> 0.63809524 | P5: =(E5-MIN(E$2:E$99))/(MAX(E$2:E$99)-MIN(E$2:E$99)) -> 0.16666667 | Q5: =(F5-MIN(F$2:F$99))/(MAX(F$2:F$99)-MIN(F$2:F$99)) -> 0.36842105 | R5: =(G5-MIN(G$2:G$99))/(MAX(G$2:G$99)-MIN(G$2:G$99)) -> 0.26829268 | S5: =(H5-MIN(H$2:H$99))/(MAX(H$2:H$99)-MIN(H$2:H$99)) -> 0.3125 | T5: =SUM(N5:S5) -> 2.4263894 | V5: 0.4 | W5: =1-V5 -> 0.6 | X5: =V5^2 * N5 -> 0.10758621 | Y5: =W5^2 * N5 -> 0.24206897 | Z5: =(N5-$N$102)^2 + (O5-$O$102)^2 + (P5-$P$102)^2 + (Q5-$Q$102)^2 + (R5-$R$102)^2 + (S5-$S$102)^2 -> 0.20303689 | AA5: =(N5-$N$103)^2+(O5-$O$103)^2+(P5-$P$103)^2+(Q5-$Q$103)^2+(R5-$R$103)^2+(S5-$S$103)^2 -> 0.10798905 | AB5: =(1/Z5) / ((1/Z5) + (1/AA5)) -> 0.34720272 | AC5: =1 - AB5 -> 0.65279728 | AE5: =IF(AB5 > AC5, 1, 2) -> 2 | AF5: =((VALUE(IF(OR(AND(AE5=2, K5="SEDANG"), AND(AE5=1, K5="TIDAK SEHAT")), 1, 0)))*1)*1 -> 0
A6: 202207 | B6: 44746 | C6: 56 | D6: 78 | E6: 49 | F6: 11 | G6: 60 | H6: 13 | I6: 78 | J6: PM2,5 | K6: SEDANG | L6: DKI4 | N6: =(C6 - MIN(C$2:C$99)) / (MAX(C$2:C$99) - MIN(C$2:C$99)) -> 0.5 | O6: =(D6-MIN(D$2:D$99))/(MAX(D$2:D$99)-MIN(D$2:D$99)) -> 0.33333333 | P6: =(E6-MIN(E$2:E$99))/(MAX(E$2:E$99)-MIN(E$2:E$99)) -> 0.33333333 | Q6: =(F6-MIN(F$2:F$99))/(MAX(F$2:F$99)-MIN(F$2:F$99)) -> 0.10526316 | R6: =(G6-MIN(G$2:G$99))/(MAX(G$2:G$99)-MIN(G$2:G$99)) -> 0.26219512 | S6: =(H6-MIN(H$2:H$99))/(MAX(H$2:H$99)-MIN(H$2:H$99)) -> 0 | T6: =SUM(N6:S6) -> 1.5341249 | V6: 0.5 | W6: =1-V6 -> 0.5 | X6: =V6^2 * N6 -> 0.125 | Y6: =W6^2 * N6 -> 0.125 | Z6: =(N6-$N$102)^2 + (O6-$O$102)^2 + (P6-$P$102)^2 + (Q6-$Q$102)^2 + (R6-$R$102)^2 + (S6-$S$102)^2 -> 0.4712992 | AA6: =(N6-$N$103)^2+(O6-$O$103)^2+(P6-$P$103)^2+(Q6-$Q$103)^2+(R6-$R$103)^2+(S6-$S$103)^2 -> 0.36413806 | AB6: =(1/Z6) / ((1/Z6) + (1/AA6)) -> 0.43586524 | AC6: =1 - AB6 -> 0.56413476 | AE6: =IF(AB6 > AC6, 1, 2) -> 2 | AF6: =((VALUE(IF(OR(AND(AE6=2, K6="SEDANG"), AND(AE6=1, K6="TIDAK SEHAT")), 1, 0)))*1)*1 -> 1
A7: 202207 | B7: 44745 | C7: 78 | D7: 126 | E7: 48 | F7: 17 | G7: 126 | H7: 25 | I7: 126 | J7: PM2,5 | K7: TIDAK SEHAT | L7: DKI2 | N7: =(C7 - MIN(C$2:C$99)) / (MAX(C$2:C$99) - MIN(C$2:C$99)) -> 0.87931034 | O7: =(D7-MIN(D$2:D$99))/(MAX(D$2:D$99)-MIN(D$2:D$99)) -> 0.79047619 | P7: =(E7-MIN(E$2:E$99))/(MAX(E$2:E$99)-MIN(E$2:E$99)) -> 0.25 | Q7: =(F7-MIN(F$2:F$99))/(MAX(F$2:F$99)-MIN(F$2:F$99)) -> 0.42105263 | R7: =(G7-MIN(G$2:G$99))/(MAX(G$2:G$99)-MIN(G$2:G$99)) -> 0.66463415 | S7: =(H7-MIN(H$2:H$99))/(MAX(H$2:H$99)-MIN(H$2:H$99)) -> 0.375 | T7: =SUM(N7:S7) -> 3.3804733 | V7: 0.6 | W7: =1 - V7 -> 0.4 | X7: =V7^2 * N7 -> 0.31655172 | Y7: =W7^2 * N7 -> 0.14068966 | Z7: =(N7-$N$102)^2 + (O7-$O$102)^2 + (P7-$P$102)^2 + (Q7-$Q$102)^2 + (R7-$R$102)^2 + (S7-$S$102)^2 -> 0.50856014 | AA7: =(N7-$N$103)^2+(O7-$O$103)^2+(P7-$P$103)^2+(Q7-$Q$103)^2+(R7-$R$103)^2+(S7-$S$103)^2 -> 0.3097599 | AB7: =(1/Z7) / ((1/Z7) + (1/AA7)) -> 0.37853148 | AC7: =1 - AB7 -> 0.62146852 | AE7: =IF(AB7 > AC7, 1, 2) -> 2 | AF7: =((VALUE(IF(OR(AND(AE7=2, K7="SEDANG"), AND(AE7=1, K7="TIDAK SEHAT")), 1, 0)))*1)*1 -> 0
A8: 202207 | B8: 44744 | C8: 81 | D8: 137 | E8: 47 | F8: 18 | G8: 106 | H8: 29 | I8: 137 | J8: PM2,5 | K8: TIDAK SEHAT | L8: DKI4 | N8: =(C8 - MIN(C$2:C$99)) / (MAX(C$2:C$99) - MIN(C$2:C$99)) -> 0.93103448 | O8: =(D8-MIN(D$2:D$99))/(MAX(D$2:D$99)-MIN(D$2:D$99)) -> 0.8952381 | P8: =(E8-MIN(E$2:E$99))/(MAX(E$2:E$99)-MIN(E$2:E$99)) -> 0.16666667 | Q8: =(F8-MIN(F$2:F$99))/(MAX(F$2:F$99)-MIN(F$2:F$99)) -> 0.47368421 | R8: =(G8-MIN(G$2:G$99))/(MAX(G$2:G$99)-MIN(G$2:G$99)) -> 0.54268293 | S8: =(H8-MIN(H$2:H$99))/(MAX(H$2:H$99)-MIN(H$2:H$99)) -> 0.5 | T8: =SUM(N8:S8) -> 3.5093064 | V8: 0.7 | W8: =1 - V8 -> 0.3 | X8: =V8^2 * N8 -> 0.4562069 | Y8: =W8^2 * N8 -> 0.083793103 | Z8: =(N8-$N$102)^2 + (O8-$O$102)^2 + (P8-$P$102)^2 + (Q8-$Q$102)^2 + (R8-$R$102)^2 + (S8-$S$102)^2 -> 0.53641793 | AA8: =(N8-$N$103)^2+(O8-$O$103)^2+(P8-$P$103)^2+(Q8-$Q$103)^2+(R8-$R$103)^2+(S8-$S$103)^2 -> 0.36842456 | AB8: =(1/Z8) / ((1/Z8) + (1/AA8)) -> 0.40716983 | AC8: =1 - AB8 -> 0.59283017 | AE8: =IF(AB8 > AC8, 1, 2) -> 2 | AF8: =((VALUE(IF(OR(AND(AE8=2, K8="SEDANG"), AND(AE8=1, K8="TIDAK SEHAT")), 1, 0)))*1)*1 -> 0
A9: 202208 | B9: 44774 | C9: 68 | D9: 109 | E9: 50 | F9: 12 | G9: 91 | H9: 19 | I9: 109 | J9: PM2,5 | K9: TIDAK SEHAT | L9: DKI4 | N9: =(C9 - MIN(C$2:C$99)) / (MAX(C$2:C$99) - MIN(C$2:C$99)) -> 0.70689655 | O9: =(D9-MIN(D$2:D$99))/(MAX(D$2:D$99)-MIN(D$2:D$99)) -> 0.62857143 | P9: =(E9-MIN(E$2:E$99))/(MAX(E$2:E$99)-MIN(E$2:E$99)) -> 0.41666667 | Q9: =(F9-MIN(F$2:F$99))/(MAX(F$2:F$99)-MIN(F$2:F$99)) -> 0.15789474 | R9: =(G9-MIN(G$2:G$99))/(MAX(G$2:G$99)-MIN(G$2:G$99)) -> 0.45121951 | S9: =(H9-MIN(H$2:H$99))/(MAX(H$2:H$99)-MIN(H$2:H$99)) -> 0.1875 | T9: =SUM(N9:S9) -> 2.5487489 | V9: 0.8 | W9: =1 - V9 -> 0.2 | X9: =V9^2 * N9 -> 0.45241379 | Y9: =W9^2 * N9 -> 0.028275862 | Z9: =(N9-$N$102)^2 + (O9-$O$102)^2 + (P9-$P$102)^2 + (Q9-$Q$102)^2 + (R9-$R$102)^2 + (S9-$S$102)^2 -> 0.34095818 | AA9: =(N9-$N$103)^2+(O9-$O$103)^2+(P9-$P$103)^2+(Q9-$Q$103)^2+(R9-$R$103)^2+(S9-$S$103)^2 -> 0.18436548 | AB9: =(1/Z9) / ((1/Z9) + (1/AA9)) -> 0.35095598 | AC9: =1 - AB9 -> 0.64904402 | AE9: =IF(AB9 > AC9, 1, 2) -> 2 | AF9: =(VALUE(IF(OR(AND(AE9=2, K9="SEDANG"), AND(AE9=1, K9="TIDAK SEHAT")), 1, 0)))*1 -> 0
A10: 202208 | B10: 44804 | C10: 85 | D10: 148 | E10: 51 | F10: 25 | G10: 74 | H10: 37 | I10: 148 | J10: PM2,5 | K10: TIDAK SEHAT | L10: DKI4 | N10: =(C10 - MIN(C$2:C$99)) / (MAX(C$2:C$99) - MIN(C$2:C$99)) -> 1 | O10: =(D10-MIN(D$2:D$99))/(MAX(D$2:D$99)-MIN(D$2:D$99)) -> 1 | P10: =(E10-MIN(E$2:E$99))/(MAX(E$2:E$99)-MIN(E$2:E$99)) -> 0.5 | Q10: =(F10-MIN(F$2:F$99))/(MAX(F$2:F$99)-MIN(F$2:F$99)) -> 0.84210526 | R10: =(G10-MIN(G$2:G$99))/(MAX(G$2:G$99)-MIN(G$2:G$99)) -> 0.34756098 | S10: =(H10-MIN(H$2:H$99))/(MAX(H$2:H$99)-MIN(H$2:H$99)) -> 0.75 | T10: =SUM(N10:S10) -> 4.4396662 | V10: 0.9 | W10: =1 - V10 -> 0.1 | X10: =V10^2 * N10 -> 0.81 | Y10: =W10^2 * N10 -> 0.01 | Z10: =(N10-$N$102)^2 + (O10-$O$102)^2 + (P10-$P$102)^2 + (Q10-$Q$102)^2 + (R10-$R$102)^2 + (S10-$S$102)^2 -> 0.68750007 | AA10: =(N10-$N$103)^2+(O10-$O$103)^2+(P10-$P$103)^2+(Q10-$Q$103)^2+(R10-$R$103)^2+(S10-$S$103)^2 -> 0.64005831 | AB10: =(1/Z10) / ((1/Z10) + (1/AA10)) -> 0.48213195 | AC10: =1 - AB10 -> 0.51786805 | AE10: =IF(AB10 > AC10, 1, 2) -> 2 | AF10: =(VALUE(IF(OR(AND(AE10=2, K10="SEDANG"), AND(AE10=1, K10="TIDAK SEHAT")), 1, 0)))*1 -> 0
A11: 202208 | B11: 44803 | C11: 59 | D11: 84 | E11: 50 | F11: 15 | G11: 56 | H11: 29 | I11: 84 | J11: PM2,5 | K11: SEDANG | L11: DKI4 | N11: =(C11 - MIN(C$2:C$99)) / (MAX(C$2:C$99) - MIN(C$2:C$99)) -> 0.55172414 | O11: =(D11-MIN(D$2:D$99))/(MAX(D$2:D$99)-MIN(D$2:D$99)) -> 0.39047619 | P11: =(E11-MIN(E$2:E$99))/(MAX(E$2:E$99)-MIN(E$2:E$99)) -> 0.41666667 | Q11: =(F11-MIN(F$2:F$99))/(MAX(F$2:F$99)-MIN(F$2:F$99)) -> 0.31578947 | R11: =(G11-MIN(G$2:G$99))/(MAX(G$2:G$99)-MIN(G$2:G$99)) -> 0.23780488 | S11: =(H11-MIN(H$2:H$99))/(MAX(H$2:H$99)-MIN(H$2:H$99)) -> 0.5 | T11: =SUM(N11:S11) -> 2.4124613 | V11: 0.1 | W11: =1 - V11 -> 0.9 | X11: =V11^2 * N11 -> 0.0055172414 | Y11: =W11^2 * N11 -> 0.44689655 | Z11: =(N11-$N$102)^2 + (O11-$O$102)^2 + (P11-$P$102)^2 + (Q11-$Q$102)^2 + (R11-$R$102)^2 + (S11-$S$102)^2 -> 0.033246608 | AA11: =(N11-$N$103)^2+(O11-$O$103)^2+(P11-$P$103)^2+(Q11-$Q$103)^2+(R11-$R$103)^2+(S11-$S$103)^2 -> 0.042206855 | AB11: =(1/Z11) / ((1/Z11) + (1/AA11)) -> 0.55937599 | AC11: =1 - AB11 -> 0.44062401 | AE11: =IF(AB11 > AC11, 1, 2) -> 1 | AF11: =(VALUE(IF(OR(AND(AE11=2, K11="SEDANG"), AND(AE11=1, K11="TIDAK SEHAT")), 1, 0)))*1 -> 0
A12: 202208 | B12: 44802 | C12: 58 | D12: 82 | E12: 49 | F12: 16 | G12: 55 | H12: 29 | I12: 82 | J12: PM2,5 | K12: SEDANG | L12: DKI4 | N12: =(C12 - MIN(C$2:C$99)) / (MAX(C$2:C$99) - MIN(C$2:C$99)) -> 0.53448276 | O12: =(D12-MIN(D$2:D$99))/(MAX(D$2:D$99)-MIN(D$2:D$99)) -> 0.37142857 | P12: =(E12-MIN(E$2:E$99))/(MAX(E$2:E$99)-MIN(E$2:E$99)) -> 0.33333333 | Q12: =(F12-MIN(F$2:F$99))/(MAX(F$2:F$99)-MIN(F$2:F$99)) -> 0.36842105 | R12: =(G12-MIN(G$2:G$99))/(MAX(G$2:G$99)-MIN(G$2:G$99)) -> 0.23170732 | S12: =(H12-MIN(H$2:H$99))/(MAX(H$2:H$99)-MIN(H$2:H$99)) -> 0.5 | T12: =SUM(N12:S12) -> 2.339373 | V12: 0.11 | W12: =1 - V12 -> 0.89 | X12: =V12^2 * N12 -> 0.0064672414 | Y12: =W12^2 * N12 -> 0.42336379 | Z12: =(N12-$N$102)^2 + (O12-$O$102)^2 + (P12-$P$102)^2 + (Q12-$Q$102)^2 + (R12-$R$102)^2 + (S12-$S$102)^2 -> 0.039213417 | AA12: =(N12-$N$103)^2+(O12-$O$103)^2+(P12-$P$103)^2+(Q12-$Q$103)^2+(R12-$R$103)^2+(S12-$S$103)^2 -> 0.050475008 | AB12: =(1/Z12) / ((1/Z12) + (1/AA12)) -> 0.56278174 | AC12: =1 - AB12 -> 0.43721826 | AE12: =IF(AB12 > AC12, 1, 2) -> 1 | AF12: =(VALUE(IF(OR(AND(AE12=2, K12="SEDANG"), AND(AE12=1, K12="TIDAK SEHAT")), 1, 0)))*1 -> 0
A13: 202208 | B13: 44801 | C13: 64 | D13: 85 | E13: 49 | F13: 17 | G13: 56 | H13: 30 | I13: 85 | J13: PM2,5 | K13: SEDANG | L13: DKI5 | N13: =(C13 - MIN(C$2:C$99)) / (MAX(C$2:C$99) - MIN(C$2:C$99)) -> 0.63793103 | O13: =(D13-MIN(D$2:D$99))/(MAX(D$2:D$99)-MIN(D$2:D$99)) -> 0.4 | P13: =(E13-MIN(E$2:E$99))/(MAX(E$2:E$99)-MIN(E$2:E$99)) -> 0.33333333 | Q13: =(F13-MIN(F$2:F$99))/(MAX(F$2:F$99)-MIN(F$2:F$99)) -> 0.42105263 | R13: =(G13-MIN(G$2:G$99))/(MAX(G$2:G$99)-MIN(G$2:G$99)) -> 0.23780488 | S13: =(H13-MIN(H$2:H$99))/(MAX(H$2:H$99)-MIN(H$2:H$99)) -> 0.53125 | T13: =SUM(N13:S13) -> 2.5613719 | V13: 0.12 | W13: =1 - V13 -> 0.88 | X13: =V13^2 * N13 -> 0.0091862069 | Y13: =W13^2 * N13 -> 0.49401379 | Z13: =(N13-$N$102)^2 + (O13-$O$102)^2 + (P13-$P$102)^2 + (Q13-$Q$102)^2 + (R13-$R$102)^2 + (S13-$S$102)^2 -> 0.028069843 | AA13: =(N13-$N$103)^2+(O13-$O$103)^2+(P13-$P$103)^2+(Q13-$Q$103)^2+(R13-$R$103)^2+(S13-$S$103)^2 -> 0.03166992 | AB13: =(1/Z13) / ((1/Z13) + (1/AA13)) -> 0.53013133 | AC13: =1 - AB13 -> 0.46986867 | AE13: =IF(AB13 > AC13, 1, 2) -> 1 | AF13: =(VALUE(IF(OR(AND(AE13=2, K13="SEDANG"), AND(AE13=1, K13="TIDAK SEHAT")), 1, 0)))*1 -> 0
A14: 202208 | B14: 44800 | C14: 80 | D14: 130 | E14: 50 | F14: 25 | G14: 57 | H14: 37 | I14: 130 | J14: PM2,5 | K14: TIDAK SEHAT | L14: DKI4 | N14: =(C14 - MIN(C$2:C$99)) / (MAX(C$2:C$99) - MIN(C$2:C$99)) -> 0.9137931 | O14: =(D14-MIN(D$2:D$99))/(MAX(D$2:D$99)-MIN(D$2:D$99)) -> 0.82857143 | P14: =(E14-MIN(E$2:E$99))/(MAX(E$2:E$99)-MIN(E$2:E$99)) -> 0.41666667 | Q14: =(F14-MIN(F$2:F$99))/(MAX(F$2:F$99)-MIN(F$2:F$99)) -> 0.84210526 | R14: =(G14-MIN(G$2:G$99))/(MAX(G$2:G$99)-MIN(G$2:G$99)) -> 0.24390244 | S14: =(H14-MIN(H$2:H$99))/(MAX(H$2:H$99)-MIN(H$2:H$99)) -> 0.75 | T14: =SUM(N14:S14) -> 3.9950389 | V14: 0.13 | W14: =1 - V14 -> 0.87 | X14: =V14^2 * N14 -> 0.015443103 | Y14: =W14^2 * N14 -> 0.69165 | Z14: =(N14-$N$102)^2 + (O14-$O$102)^2 + (P14-$P$102)^2 + (Q14-$Q$102)^2 + (R14-$R$102)^2 + (S14-$S$102)^2 -> 0.44329558 | AA14: =(N14-$N$103)^2+(O14-$O$103)^2+(P14-$P$103)^2+(Q14-$Q$103)^2+(R14-$R$103)^2+(S14-$S$103)^2 -> 0.44105125 | AB14: =(1/Z14) / ((1/Z14) + (1/AA14)) -> 0.49873108 | AC14: =1 - AB14 -> 0.50126892 | AE14: =IF(AB14 > AC14, 1, 2) -> 2 | AF14: =(VALUE(IF(OR(AND(AE14=2, K14="SEDANG"), AND(AE14=1, K14="TIDAK SEHAT")), 1, 0)))*1 -> 0
A15: 202208 | B15: 44799 | C15: 76 | D15: 119 | E15: 53 | F15: 19 | G15: 53 | H15: 31 | I15: 119 | J15: PM2,5 | K15: TIDAK SEHAT | L15: DKI4 | N15: =(C15 - MIN(C$2:C$99)) / (MAX(C$2:C$99) - MIN(C$2:C$99)) -> 0.84482759 | O15: =(D15-MIN(D$2:D$99))/(MAX(D$2:D$99)-MIN(D$2:D$99)) -> 0.72380952 | P15: =(E15-MIN(E$2:E$99))/(MAX(E$2:E$99)-MIN(E$2:E$99)) -> 0.66666667 | Q15: =(F15-MIN(F$2:F$99))/(MAX(F$2:F$99)-MIN(F$2:F$99)) -> 0.52631579 | R15: =(G15-MIN(G$2:G$99))/(MAX(G$2:G$99)-MIN(G$2:G$99)) -> 0.2195122 | S15: =(H15-MIN(H$2:H$99))/(MAX(H$2:H$99)-MIN(H$2:H$99)) -> 0.5625 | T15: =SUM(N15:S15) -> 3.5436318 | V15: 0.14 | W15: =1 - V15 -> 0.86 | X15: =V15^2 * N15 -> 0.016558621 | Y15: =W15^2 * N15 -> 0.62483448 | Z15: =(N15-$N$102)^2 + (O15-$O$102)^2 + (P15-$P$102)^2 + (Q15-$Q$102)^2 + (R15-$R$102)^2 + (S15-$S$102)^2 -> 0.1891396 | AA15: =(N15-$N$103)^2+(O15-$O$103)^2+(P15-$P$103)^2+(Q15-$Q$103)^2+(R15-$R$103)^2+(S15-$S$103)^2 -> 0.17321816 | AB15: =(1/Z15) / ((1/Z15) + (1/AA15)) -> 0.47803077 | AC15: =1 - AB15 -> 0.52196923 | AE15: =IF(AB15 > AC15, 1, 2) -> 2 | AF15: =(VALUE(IF(OR(AND(AE15=2, K15="SEDANG"), AND(AE15=1, K15="TIDAK SEHAT")), 1, 0)))*1 -> 0
A16: 202208 | B16: 44798 | C16: 64 | D16: 98 | E16: 50 | F16: 12 | G16: 66 | H16: 19 | I16: 98 | J16: PM2,5 | K16: SEDANG | L16: DKI4 | N16: =(C16 - MIN(C$2:C$99)) / (MAX(C$2:C$99) - MIN(C$2:C$99)) -> 0.63793103 | O16: =(D16-MIN(D$2:D$99))/(MAX(D$2:D$99)-MIN(D$2:D$99)) -> 0.52380952 | P16: =(E16-MIN(E$2:E$99))/(MAX(E$2:E$99)-MIN(E$2:E$99)) -> 0.41666667 | Q16: =(F16-MIN(F$2:F$99))/(MAX(F$2:F$99)-MIN(F$2:F$99)) -> 0.15789474 | R16: =(G16-MIN(G$2:G$99))/(MAX(G$2:G$99)-MIN(G$2:G$99)) -> 0.29878049 | S16: =(H16-MIN(H$2:H$99))/(MAX(H$2:H$99)-MIN(H$2:H$99)) -> 0.1875 | T16: =SUM(N16:S16) -> 2.2225824 | V16: 0.15 | W16: =1 - V16 -> 0.85 | X16: =V16^2 * N16 -> 0.014353448 | Y16: =W16^2 * N16 -> 0.46090517 | Z16: =(N16-$N$102)^2 + (O16-$O$102)^2 + (P16-$P$102)^2 + (Q16-$Q$102)^2 + (R16-$R$102)^2 + (S16-$S$102)^2 -> 0.24547712 | AA16: =(N16-$N$103)^2+(O16-$O$103)^2+(P16-$P$103)^2+(Q16-$Q$103)^2+(R16-$R$103)^2+(S16-$S$103)^2 -> 0.14122292 | AB16: =(1/Z16) / ((1/Z16) + (1/AA16)) -> 0.36520017 | AC16: =1 - AB16 -> 0.63479983 | AE16: =IF(AB16 > AC16, 1, 2) -> 2 | AF16: =(VALUE(IF(OR(AND(AE16=2, K16="SEDANG"), AND(AE16=1, K16="TIDAK SEHAT")), 1, 0)))*1 -> 1
A17: 202208 | B17: 44797 | C17: 71 | D17: 119 | E17: 50 | F17: 15 | G17: 82 | H17: 20 | I17: 119 | J17: PM2,5 | K17: TIDAK SEHAT | L17: DKI4 | N17: =(C17 - MIN(C$2:C$99)) / (MAX(C$2:C$99) - MIN(C$2:C$99)) -> 0.75862069 | O17: =(D17-MIN(D$2:D$99))/(MAX(D$2:D$99)-MIN(D$2:D$99)) -> 0.72380952 | P17: =(E17-MIN(E$2:E$99))/(MAX(E$2:E$99)-MIN(E$2:E$99)) -> 0.41666667 | Q17: =(F17-MIN(F$2:F$99))/(MAX(F$2:F$99)-MIN(F$2:F$99)) -> 0.31578947 | R17: =(G17-MIN(G$2:G$99))/(MAX(G$2:G$99)-MIN(G$2:G$99)) -> 0.39634146 | S17: =(H17-MIN(H$2:H$99))/(MAX(H$2:H$99)-MIN(H$2:H$99)) -> 0.21875 | T17: =SUM(N17:S17) -> 2.8299778 | V17: 0.17 | W17: =1 - V17 -> 0.83 | X17: =V17^2 * N17 -> 0.021924138 | Y17: =W17^2 * N17 -> 0.52261379 | Z17: =(N17-$N$102)^2 + (O17-$O$102)^2 + (P17-$P$102)^2 + (Q17-$Q$102)^2 + (R17-$R$102)^2 + (S17-$S$102)^2 -> 0.28080004 | AA17: =(N17-$N$103)^2+(O17-$O$103)^2+(P17-$P$103)^2+(Q17-$Q$103)^2+(R17-$R$103)^2+(S17-$S$103)^2 -> 0.13471138 | AB17: =(1/Z17) / ((1/Z17) + (1/AA17)) -> 0.32420621 | AC17: =1 - AB17 -> 0.67579379 | AE17: =IF(AB17 > AC17, 1, 2) -> 2 | AF17: =(VALUE(IF(OR(AND(AE17=2, K17="SEDANG"), AND(AE17=1, K17="TIDAK SEHAT")), 1, 0)))*1 -> 0
A18: 202208 | B18: 44796 | C18: 76 | D18: 116 | E18: 49 | F18: 17 | G18: 81 | H18: 27 | I18: 116 | J18: PM2,5 | K18: TIDAK SEHAT | L18: DKI4 | N18: =(C18 - MIN(C$2:C$99)) / (MAX(C$2:C$99) - MIN(C$2:C$99)) -> 0.84482759 | O18: =(D18-MIN(D$2:D$99))/(MAX(D$2:D$99)-MIN(D$2:D$99)) -> 0.6952381 | P18: =(E18-MIN(E$2:E$99))/(MAX(E$2:E$99)-MIN(E$2:E$99)) -> 0.33333333 | Q18: =(F18-MIN(F$2:F$99))/(MAX(F$2:F$99)-MIN(F$2:F$99)) -> 0.42105263 | R18: =(G18-MIN(G$2:G$99))/(MAX(G$2:G$99)-MIN(G$2:G$99)) -> 0.3902439 | S18: =(H18-MIN(H$2:H$99))/(MAX(H$2:H$99)-MIN(H$2:H$99)) -> 0.4375 | T18: =SUM(N18:S18) -> 3.1221955 | V18: 0.18 | W18: =1 - V18 -> 0.82 | X18: =V18^2 * N18 -> 0.027372414 | Y18: =W18^2 * N18 -> 0.56806207 | Z18: =(N18-$N$102)^2 + (O18-$O$102)^2 + (P18-$P$102)^2 + (Q18-$Q$102)^2 + (R18-$R$102)^2 + (S18-$S$102)^2 -> 0.20104576 | AA18: =(N18-$N$103)^2+(O18-$O$103)^2+(P18-$P$103)^2+(Q18-$Q$103)^2+(R18-$R$103)^2+(S18-$S$103)^2 -> 0.094460207 | AB18: =(1/Z18) / ((1/Z18) + (1/AA18)) -> 0.31965584 | AC18: =1 - AB18 -> 0.68034416 | AE18: =IF(AB18 > AC18, 1, 2) -> 2 | AF18: =(VALUE(IF(OR(AND(AE18=2, K18="SEDANG"), AND(AE18=1, K18="TIDAK SEHAT")), 1, 0)))*1 -> 0
A19: 202208 | B19: 44795 | C19: 57 | D19: 78 | E19: 49 | F19: 13 | G19: 79 | H19: 22 | I19: 79 | J19: O3 | K19: SEDANG | L19: DKI2 | N19: =(C19 - MIN(C$2:C$99)) / (MAX(C$2:C$99) - MIN(C$2:C$99)) -> 0.51724138 | O19: =(D19-MIN(D$2:D$99))/(MAX(D$2:D$99)-MIN(D$2:D$99)) -> 0.33333333 | P19: =(E19-MIN(E$2:E$99))/(MAX(E$2:E$99)-MIN(E$2:E$99)) -> 0.33333333 | Q19: =(F19-MIN(F$2:F$99))/(MAX(F$2:F$99)-MIN(F$2:F$99)) -> 0.21052632 | R19: =(G19-MIN(G$2:G$99))/(MAX(G$2:G$99)-MIN(G$2:G$99)) -> 0.37804878 | S19: =(H19-MIN(H$2:H$99))/(MAX(H$2:H$99)-MIN(H$2:H$99)) -> 0.28125 | T19: =SUM(N19:S19) -> 2.0537331 | V19: 0.19 | W19: =1 - V19 -> 0.81 | X19: =V19^2 * N19 -> 0.018672414 | Y19: =W19^2 * N19 -> 0.33936207 | Z19: =(N19-$N$102)^2+(O19-$O$102)^2+(P19-$P$102)^2+(Q19-$Q$102)^2+(R19-$R$102)^2+(S19-$S$102)^2 -> 0.20616358 | AA19: =(N19-$N$103)^2+(O19-$O$103)^2+(P19-$P$103)^2+(Q19-$Q$103)^2+(R19-$R$103)^2+(S19-$S$103)^2 -> 0.13762803 | AB19: =(1/Z19) / ((1/Z19) + (1/AA19)) -> 0.40032399 | AC19: =1 - AB19 -> 0.59967601 | AE19: =IF(AB19 > AC19, 1, 2) -> 2 | AF19: =(VALUE(IF(OR(AND(AE19=2, K19="SEDANG"), AND(AE19=1, K19="TIDAK SEHAT")), 1, 0)))*1 -> 1
A20: 202208 | B20: 44794 | C20: 59 | D20: 101 | E20: 49 | F20: 13 | G20: 65 | H20: 17 | I20: 101 | J20: PM2,5 | K20: TIDAK SEHAT | L20: DKI4 | N20: =(C20 - MIN(C$2:C$99)) / (MAX(C$2:C$99) - MIN(C$2:C$99)) -> 0.55172414 | O20: =(D20-MIN(D$2:D$99))/(MAX(D$2:D$99)-MIN(D$2:D$99)) -> 0.55238095 | P20: =(E20-MIN(E$2:E$99))/(MAX(E$2:E$99)-MIN(E$2:E$99)) -> 0.33333333 | Q20: =(F20-MIN(F$2:F$99))/(MAX(F$2:F$99)-MIN(F$2:F$99)) -> 0.21052632 | R20: =(G20-MIN(G$2:G$99))/(MAX(G$2:G$99)-MIN(G$2:G$99)) -> 0.29268293 | S20: =(H20-MIN(H$2:H$99))/(MAX(H$2:H$99)-MIN(H$2:H$99)) -> 0.125 | T20: =SUM(N20:S20) -> 2.0656477 | V20: 0.2 | W20: =1 - V20 -> 0.8 | X20: =V20^2 * N20 -> 0.022068966 | Y20: =W20^2 * N20 -> 0.35310345 | Z20: =(N20-$N$102)^2 + (O20-$O$102)^2 + (P20-$P$102)^2 + (Q20-$Q$102)^2 + (R20-$R$102)^2 + (S20-$S$102)^2 -> 0.2814094 | AA20: =(N20-$N$103)^2+(O20-$O$103)^2+(P20-$P$103)^2+(Q20-$Q$103)^2+(R20-$R$103)^2+(S20-$S$103)^2 -> 0.16967211 | AB20: =(1/Z20) / ((1/Z20) + (1/AA20)) -> 0.37614512 | AC20: =1 - AB20 -> 0.62385488 | AE20: =IF(AB20 > AC20, 1, 2) -> 2 | AF20: =(VALUE(IF(OR(AND(AE20=2, K20="SEDANG"), AND(AE20=1, K20="TIDAK SEHAT")), 1, 0)))*1 -> 0
A21: 202208 | B21: 44793 | C21: 76 | D21: 117 | E21: 50 | F21: 14 | G21: 69 | H21: 18 | I21: 117 | J21: PM2,5 | K21: TIDAK SEHAT | L21: DKI4 | N21: =(C21 - MIN(C$2:C$99)) / (MAX(C$2:C$99) - MIN(C$2:C$99)) -> 0.84482759 | O21: =(D21-MIN(D$2:D$99))/(MAX(D$2:D$99)-MIN(D$2:D$99)) -> 0.7047619 | P21: =(E21-MIN(E$2:E$99))/(MAX(E$2:E$99)-MIN(E$2:E$99)) -> 0.41666667 | Q21: =(F21-MIN(F$2:F$99))/(MAX(F$2:F$99)-MIN(F$2:F$99)) -> 0.26315789 | R21: =(G21-MIN(G$2:G$99))/(MAX(G$2:G$99)-MIN(G$2:G$99)) -> 0.31707317 | S21: =(H21-MIN(H$2:H$99))/(MAX(H$2:H$99)-MIN(H$2:H$99)) -> 0.15625 | T21: =SUM(N21:S21) -> 2.7027372 | V21: 0.21 | W21: =1 - V21 -> 0.79 | X21: =V21^2 * N21 -> 0.037256897 | Y21: =W21^2 * N21 -> 0.5272569 | Z21: =(N21-$N$102)^2 + (O21-$O$102)^2 + (P21-$P$102)^2 + (Q21-$Q$102)^2 + (R21-$R$102)^2 + (S21-$S$102)^2 -> 0.34556508 | AA21: =(N21-$N$103)^2+(O21-$O$103)^2+(P21-$P$103)^2+(Q21-$Q$103)^2+(R21-$R$103)^2+(S21-$S$103)^2 -> 0.19137128 | AB21: =(1/Z21) / ((1/Z21) + (1/AA21)) -> 0.35641333 | AC21: =1 - AB21 -> 0.64358667 | AE21: =IF(AB21 > AC21, 1, 2) -> 2 | AF21: =(VALUE(IF(OR(AND(AE21=2, K21="SEDANG"), AND(AE21=1, K21="TIDAK SEHAT")), 1, 0)))*1 -> 0
A22: 202208 | B22: 44792 | C22: 70 | D22: 105 | E22: 49 | F22: 14 | G22: 66 | H22: 26 | I22: 105 | J22: PM2,5 | K22: TIDAK SEHAT | L22: DKI4 | N22: =(C22 - MIN(C$2:C$99)) / (MAX(C$2:C$99) - MIN(C$2:C$99)) -> 0.74137931 | O22: =(D22-MIN(D$2:D$99))/(MAX(D$2:D$99)-MIN(D$2:D$99)) -> 0.59047619 | P22: =(E22-MIN(E$2:E$99))/(MAX(E$2:E$99)-MIN(E$2:E$99)) -> 0.33333333 | Q22: =(F22-MIN(F$2:F$99))/(MAX(F$2:F$99)-MIN(F$2:F$99)) -> 0.26315789 | R22: =(G22-MIN(G$2:G$99))/(MAX(G$2:G$99)-MIN(G$2:G$99)) -> 0.29878049 | S22: =(H22-MIN(H$2:H$99))/(MAX(H$2:H$99)-MIN(H$2:H$99)) -> 0.40625 | T22: =SUM(N22:S22) -> 2.6333772 | V22: 0.22 | W22: =1 - V22 -> 0.78 | X22: =V22^2 * N22 -> 0.035882759 | Y22: =W22^2 * N22 -> 0.45105517 | Z22: =(N22-$N$102)^2 + (O22-$O$102)^2 + (P22-$P$102)^2 + (Q22-$Q$102)^2 + (R22-$R$102)^2 + (S22-$S$102)^2 -> 0.13437479 | AA22: =(N22-$N$103)^2+(O22-$O$103)^2+(P22-$P$103)^2+(Q22-$Q$103)^2+(R22-$R$103)^2+(S22-$S$103)^2 -> 0.055696843 | AB22: =(1/Z22) / ((1/Z22) + (1/AA22)) -> 0.29303081 | AC22: =1 - AB22 -> 0.70696919 | AE22: =IF(AB22 > AC22, 1, 2) -> 2 | AF22: =(VALUE(IF(OR(AND(AE22=2, K22="SEDANG"), AND(AE22=1, K22="TIDAK SEHAT")), 1, 0)))*1 -> 0
A23: 202208 | B23: 44791 | C23: 64 | D23: 89 | E23: 49 | F23: 25 | G23: 84 | H23: 28 | I23: 89 | J23: PM2,5 | K23: SEDANG | L23: DKI4 | N23: =(C23 - MIN(C$2:C$99)) / (MAX(C$2:C$99) - MIN(C$2:C$99)) -> 0.63793103 | O23: =(D23-MIN(D$2:D$99))/(MAX(D$2:D$99)-MIN(D$2:D$99)) -> 0.43809524 | P23: =(E23-MIN(E$2:E$99))/(MAX(E$2:E$99)-MIN(E$2:E$99)) -> 0.33333333 | Q23: =(F23-MIN(F$2:F$99))/(MAX(F$2:F$99)-MIN(F$2:F$99)) -> 0.84210526 | R23: =(G23-MIN(G$2:G$99))/(MAX(G$2:G$99)-MIN(G$2:G$99)) -> 0.40853659 | S23: =(H23-MIN(H$2:H$99))/(MAX(H$2:H$99)-MIN(H$2:H$99)) -> 0.46875 | T23: =SUM(N23:S23) -> 3.1287515 | V23: 0.23 | W23: =1 - V23 -> 0.77 | X23: =V23^2 * N23 -> 0.033746552 | Y23: =W23^2 * N23 -> 0.37822931 | Z23: =(N23-$N$102)^2 + (O23-$O$102)^2 + (P23-$P$102)^2 + (Q23-$Q$102)^2 + (R23-$R$102)^2 + (S23-$S$102)^2 -> 0.22023988 | AA23: =(N23-$N$103)^2+(O23-$O$103)^2+(P23-$P$103)^2+(Q23-$Q$103)^2+(R23-$R$103)^2+(S23-$S$103)^2 -> 0.1951815 | AB23: =(1/Z23) / ((1/Z23) + (1/AA23)) -> 0.4698398 | AC23: =1 - AB23 -> 0.5301602 | AE23: =IF(AB23 > AC23, 1, 2) -> 2 | AF23: =(VALUE(IF(OR(AND(AE23=2, K23="SEDANG"), AND(AE23=1, K23="TIDAK SEHAT")), 1, 0)))*1 -> 1
A24: 202208 | B24: 44790 | C24: 55 | D24: 78 | E24: 48 | F24: 17 | G24: 108 | H24: 25 | I24: 108 | J24: O3 | K24: TIDAK SEHAT | L24: DKI2 | N24: =(C24 - MIN(C$2:C$99)) / (MAX(C$2:C$99) - MIN(C$2:C$99)) -> 0.48275862 | O24: =(D24-MIN(D$2:D$99))/(MAX(D$2:D$99)-MIN(D$2:D$99)) -> 0.33333333 | P24: =(E24-MIN(E$2:E$99))/(MAX(E$2:E$99)-MIN(E$2:E$99)) -> 0.25 | Q24: =(F24-MIN(F$2:F$99))/(MAX(F$2:F$99)-MIN(F$2:F$99)) -> 0.42105263 | R24: =(G24-MIN(G$2:G$99))/(MAX(G$2:G$99)-MIN(G$2:G$99)) -> 0.55487805 | S24: =(H24-MIN(H$2:H$99))/(MAX(H$2:H$99)-MIN(H$2:H$99)) -> 0.375 | T24: =SUM(N24:S24) -> 2.4170226 | V24: 0.24 | W24: =1 - V24 -> 0.76 | X24: =V24^2 * N24 -> 0.027806897 | Y24: =W24^2 * N24 -> 0.27884138 | Z24: =(N24-$N$102)^2 + (O24-$O$102)^2 + (P24-$P$102)^2 + (Q24-$Q$102)^2 + (R24-$R$102)^2 + (S24-$S$102)^2 -> 0.23624239 | AA24: =(N24-$N$103)^2+(O24-$O$103)^2+(P24-$P$103)^2+(Q24-$Q$103)^2+(R24-$R$103)^2+(S24-$S$103)^2 -> 0.16037087 | AB24: =(1/Z24) / ((1/Z24) + (1/AA24)) -> 0.40435075 | AC24: =1 - AB24 -> 0.59564925 | AE24: =IF(AB24 > AC24, 1, 2) -> 2 | AF24: =(VALUE(IF(OR(AND(AE24=2, K24="SEDANG"), AND(AE24=1, K24="TIDAK SEHAT")), 1, 0)))*1 -> 0
A25: 202208 | B25: 44789 | C25: 61 | D25: 89 | E25: 51 | F25: 15 | G25: 181 | H25: 33 | I25: 181 | J25: O3 | K25: TIDAK SEHAT | L25: DKI2 | N25: =(C25 - MIN(C$2:C$99)) / (MAX(C$2:C$99) - MIN(C$2:C$99)) -> 0.5862069 | O25: =(D25-MIN(D$2:D$99))/(MAX(D$2:D$99)-MIN(D$2:D$99)) -> 0.43809524 | P25: =(E25-MIN(E$2:E$99))/(MAX(E$2:E$99)-MIN(E$2:E$99)) -> 0.5 | Q25: =(F25-MIN(F$2:F$99))/(MAX(F$2:F$99)-MIN(F$2:F$99)) -> 0.31578947 | R25: =(G25-MIN(G$2:G$99))/(MAX(G$2:G$99)-MIN(G$2:G$99)) -> 1 | S25: =(H25-MIN(H$2:H$99))/(MAX(H$2:H$99)-MIN(H$2:H$99)) -> 0.625 | T25: =SUM(N25:S25) -> 3.4650916 | V25: 0.25 | W25: =1 - V25 -> 0.75 | X25: =V25^2 * N25 -> 0.036637931 | Y25: =W25^2 * N25 -> 0.32974138 | Z25: =(N25-$N$102)^2 + (O25-$O$102)^2 + (P25-$P$102)^2 + (Q25-$Q$102)^2 + (R25-$R$102)^2 + (S25-$S$102)^2 -> 0.68739194 | AA25: =(N25-$N$103)^2+(O25-$O$103)^2+(P25-$P$103)^2+(Q25-$Q$103)^2+(R25-$R$103)^2+(S25-$S$103)^2 -> 0.55833787 | AB25: =(1/Z25) / ((1/Z25) + (1/AA25)) -> 0.44820142 | AC25: =1 - AB25 -> 0.55179858 | AE25: =IF(AB25 > AC25, 1, 2) -> 2 | AF25: =(VALUE(IF(OR(AND(AE25=2, K25="SEDANG"), AND(AE25=1, K25="TIDAK SEHAT")), 1, 0)))*1 -> 0
A26: 202208 | B26: 44788 | C26: 64 | D26: 84 | E26: 50 | F26: 17 | G26: 63 | H26: 28 | I26: 84 | J26: PM2,5 | K26: SEDANG | L26: DKI4 | N26: =(C26 - MIN(C$2:C$99)) / (MAX(C$2:C$99) - MIN(C$2:C$99)) -> 0.63793103 | O26: =(D26-MIN(D$2:D$99))/(MAX(D$2:D$99)-MIN(D$2:D$99)) -> 0.39047619 | P26: =(E26-MIN(E$2:E$99))/(MAX(E$2:E$99)-MIN(E$2:E$99)) -> 0.41666667 | Q26: =(F26-MIN(F$2:F$99))/(MAX(F$2:F$99)-MIN(F$2:F$99)) -> 0.42105263 | R26: =(G26-MIN(G$2:G$99))/(MAX(G$2:G$99)-MIN(G$2:G$99)) -> 0.2804878 | S26: =(H26-MIN(H$2:H$99))/(MAX(H$2:H$99)-MIN(H$2:H$99)) -> 0.46875 | T26: =SUM(N26:S26) -> 2.6153643 | V26: 0.26 | W26: =1 - V26 -> 0.74 | X26: =V26^2 * N26 -> 0.043124138 | Y26: =W26^2 * N26 -> 0.34933103 | Z26: =(N26-$N$102)^2 + (O26-$O$102)^2 + (P26-$P$102)^2 + (Q26-$Q$102)^2 + (R26-$R$102)^2 + (S26-$S$102)^2 -> 0.026046201 | AA26: =(N26-$N$103)^2+(O26-$O$103)^2+(P26-$P$103)^2+(Q26-$Q$103)^2+(R26-$R$103)^2+(S26-$S$103)^2 -> 0.014875186 | AB26: =(1/Z26) / ((1/Z26) + (1/AA26)) -> 0.36350639 | AC26: =1 - AB26 -> 0.63649361 | AE26: =IF(AB26 > AC26, 1, 2) -> 2 | AF26: =(VALUE(IF(OR(AND(AE26=2, K26="SEDANG"), AND(AE26=1, K26="TIDAK SEHAT")), 1, 0)))*1 -> 1
A27: 202208 | B27: 44787 | C27: 68 | D27: 93 | E27: 50 | F27: 14 | G27: 80 | H27: 20 | I27: 93 | J27: PM2,5 | K27: SEDANG | L27: DKI4 | N27: =(C27 - MIN(C$2:C$99)) / (MAX(C$2:C$99) - MIN(C$2:C$99)) -> 0.70689655 | O27: =(D27-MIN(D$2:D$99))/(MAX(D$2:D$99)-MIN(D$2:D$99)) -> 0.47619048 | P27: =(E27-MIN(E$2:E$99))/(MAX(E$2:E$99)-MIN(E$2:E$99)) -> 0.41666667 | Q27: =(F27-MIN(F$2:F$99))/(MAX(F$2:F$99)-MIN(F$2:F$99)) -> 0.26315789 | R27: =(G27-MIN(G$2:G$99))/(MAX(G$2:G$99)-MIN(G$2:G$99)) -> 0.38414634 | S27: =(H27-MIN(H$2:H$99))/(MAX(H$2:H$99)-MIN(H$2:H$99)) -> 0.21875 | T27: =SUM(N27:S27) -> 2.4658079 | V27: 0.27 | W27: =1 - V27 -> 0.73 | X27: =V27^2 * N27 -> 0.051532759 | Y27: =W27^2 * N27 -> 0.37670517 | Z27: =(N27-$N$102)^2 + (O27-$O$102)^2 + (P27-$P$102)^2 + (Q27-$Q$102)^2 + (R27-$R$102)^2 + (S27-$S$102)^2 -> 0.20528524 | AA27: =(N27-$N$103)^2+(O27-$O$103)^2+(P27-$P$103)^2+(Q27-$Q$103)^2+(R27-$R$103)^2+(S27-$S$103)^2 -> 0.092399598 | AB27: =(1/Z27) / ((1/Z27) + (1/AA27)) -> 0.31039404 | AC27: =1 - AB27 -> 0.68960596 | AE27: =IF(AB27 > AC27, 1, 2) -> 2 | AF27: =(VALUE(IF(OR(AND(AE27=2, K27="SEDANG"), AND(AE27=1, K27="TIDAK SEHAT")), 1, 0)))*1 -> 1
A28: 202208 | B28: 44786 | C28: 58 | D28: 77 | E28: 48 | F28: 21 | G28: 76 | H28: 36 | I28: 77 | J28: PM2,5 | K28: SEDANG | L28: DKI5 | N28: =(C28 - MIN(C$2:C$99)) / (MAX(C$2:C$99) - MIN(C$2:C$99)) -> 0.53448276 | O28: =(D28-MIN(D$2:D$99))/(MAX(D$2:D$99)-MIN(D$2:D$99)) -> 0.32380952 | P28: =(E28-MIN(E$2:E$99))/(MAX(E$2:E$99)-MIN(E$2:E$99)) -> 0.25 | Q28: =(F28-MIN(F$2:F$99))/(MAX(F$2:F$99)-MIN(F$2:F$99)) -> 0.63157895 | R28: =(G28-MIN(G$2:G$99))/(MAX(G$2:G$99)-MIN(G$2:G$99)) -> 0.3597561 | S28: =(H28-MIN(H$2:H$99))/(MAX(H$2:H$99)-MIN(H$2:H$99)) -> 0.71875 | T28: =SUM(N28:S28) -> 2.8183773 | V28: 0.28 | W28: =1 - V28 -> 0.72 | X28: =V28^2 * N28 -> 0.041903448 | Y28: =W28^2 * N28 -> 0.27707586 | Z28: =(N28-$N$102)^2 + (O28-$O$102)^2 + (P28-$P$102)^2 + (Q28-$Q$102)^2 + (R28-$R$102)^2 + (S28-$S$102)^2 -> 0.15254246 | AA28: =(N28-$N$103)^2+(O28-$O$103)^2+(P28-$P$103)^2+(Q28-$Q$103)^2+(R28-$R$103)^2+(S28-$S$103)^2 -> 0.1970721 | AB28: =(1/Z28) / ((1/Z28) + (1/AA28)) -> 0.5636839 | AC28: =1 - AB28 -> 0.4363161 | AE28: =IF(AB28 > AC28, 1, 2) -> 1 | AF28: =(VALUE(IF(OR(AND(AE28=2, K28="SEDANG"), AND(AE28=1, K28="TIDAK SEHAT")), 1, 0)))*1 -> 0
A29: 202208 | B29: 44785 | C29: 65 | D29: 94 | E29: 49 | F29: 17 | G29: 97 | H29: 25 | I29: 97 | J29: O3 | K29: SEDANG | L29: DKI2 | N29: =(C29 - MIN(C$2:C$99)) / (MAX(C$2:C$99) - MIN(C$2:C$99)) -> 0.65517241 | O29: =(D29-MIN(D$2:D$99))/(MAX(D$2:D$99)-MIN(D$2:D$99)) -> 0.48571429 | P29: =(E29-MIN(E$2:E$99))/(MAX(E$2:E$99)-MIN(E$2:E$99)) -> 0.33333333 | Q29: =(F29-MIN(F$2:F$99))/(MAX(F$2:F$99)-MIN(F$2:F$99)) -> 0.42105263 | R29: =(G29-MIN(G$2:G$99))/(MAX(G$2:G$99)-MIN(G$2:G$99)) -> 0.48780488 | S29: =(H29-MIN(H$2:H$99))/(MAX(H$2:H$99)-MIN(H$2:H$99)) -> 0.375 | T29: =SUM(N29:S29) -> 2.7580775 | V29: 0.29 | W29: =1 - V29 -> 0.71 | X29: =V29^2 * N29 -> 0.0551 | Y29: =W29^2 * N29 -> 0.33027241 | Z29: =(N29-$N$102)^2 + (O29-$O$102)^2 + (P29-$P$102)^2 + (Q29-$Q$102)^2 + (R29-$R$102)^2 + (S29-$S$102)^2 -> 0.1455107 | AA29: =(N29-$N$103)^2+(O29-$O$103)^2+(P29-$P$103)^2+(Q29-$Q$103)^2+(R29-$R$103)^2+(S29-$S$103)^2 -> 0.051881353 | AB29: =(1/Z29) / ((1/Z29) + (1/AA29)) -> 0.26283405 | AC29: =1 - AB29 -> 0.73716595 | AE29: =IF(AB29 > AC29, 1, 2) -> 2 | AF29: =(VALUE(IF(OR(AND(AE29=2, K29="SEDANG"), AND(AE29=1, K29="TIDAK SEHAT")), 1, 0)))*1 -> 1
A30: 202208 | B30: 44784 | C30: 74 | D30: 107 | E30: 52 | F30: 19 | G30: 80 | H30: 27 | I30: 107 | J30: PM2,5 | K30: TIDAK SEHAT | L30: DKI4 | N30: =(C30 - MIN(C$2:C$99)) / (MAX(C$2:C$99) - MIN(C$2:C$99)) -> 0.81034483 | O30: =(D30-MIN(D$2:D$99))/(MAX(D$2:D$99)-MIN(D$2:D$99)) -> 0.60952381 | P30: =(E30-MIN(E$2:E$99))/(MAX(E$2:E$99)-MIN(E$2:E$99)) -> 0.58333333 | Q30: =(F30-MIN(F$2:F$99))/(MAX(F$2:F$99)-MIN(F$2:F$99)) -> 0.52631579 | R30: =(G30-MIN(G$2:G$99))/(MAX(G$2:G$99)-MIN(G$2:G$99)) -> 0.38414634 | S30: =(H30-MIN(H$2:H$99))/(MAX(H$2:H$99)-MIN(H$2:H$99)) -> 0.4375 | T30: =SUM(N30:S30) -> 3.3511641 | V30: 0.3 | W30: =1 - V30 -> 0.7 | X30: =V30^2 * N30 -> 0.072931034 | Y30: =W30^2 * N30 -> 0.39706897 | Z30: =(N30-$N$102)^2 + (O30-$O$102)^2 + (P30-$P$102)^2 + (Q30-$Q$102)^2 + (R30-$R$102)^2 + (S30-$S$102)^2 -> 0.14597523 | AA30: =(N30-$N$103)^2+(O30-$O$103)^2+(P30-$P$103)^2+(Q30-$Q$103)^2+(R30-$R$103)^2+(S30-$S$103)^2 -> 0.079573344 | AB30: =(1/Z30) / ((1/Z30) + (1/AA30)) -> 0.35279915 | AC30: =1 - AB30 -> 0.64720085 | AE30: =IF(AB30 > AC30, 1, 2) -> 2 | AF30: =(VALUE(IF(OR(AND(AE30=2, K30="SEDANG"), AND(AE30=1, K30="TIDAK SEHAT")), 1, 0)))*1 -> 0
A31: 202208 | B31: 44783 | C31: 73 | D31: 116 | E31: 49 | F31: 19 | G31: 82 | H31: 29 | I31: 116 | J31: PM2,5 | K31: TIDAK SEHAT | L31: DKI4 | N31: =(C31 - MIN(C$2:C$99)) / (MAX(C$2:C$99) - MIN(C$2:C$99)) -> 0.79310345 | O31: =(D31-MIN(D$2:D$99))/(MAX(D$2:D$99)-MIN(D$2:D$99)) -> 0.6952381 | P31: =(E31-MIN(E$2:E$99))/(MAX(E$2:E$99)-MIN(E$2:E$99)) -> 0.33333333 | Q31: =(F31-MIN(F$2:F$99))/(MAX(F$2:F$99)-MIN(F$2:F$99)) -> 0.52631579 | R31: =(G31-MIN(G$2:G$99))/(MAX(G$2:G$99)-MIN(G$2:G$99)) -> 0.39634146 | S31: =(H31-MIN(H$2:H$99))/(MAX(H$2:H$99)-MIN(H$2:H$99)) -> 0.5 | T31: =SUM(N31:S31) -> 3.2443321 | V31: 0.31 | W31: =1 - V31 -> 0.69 | X31: =V31^2 * N31 -> 0.076217241 | Y31: =W31^2 * N31 -> 0.37759655 | Z31: =(N31-$N$102)^2 + (O31-$O$102)^2 + (P31-$P$102)^2 + (Q31-$Q$102)^2 + (R31-$R$102)^2 + (S31-$S$102)^2 -> 0.17138795 | AA31: =(N31-$N$103)^2+(O31-$O$103)^2+(P31-$P$103)^2+(Q31-$Q$103)^2+(R31-$R$103)^2+(S31-$S$103)^2 -> 0.089265597 | AB31: =(1/Z31) / ((1/Z31) + (1/AA31)) -> 0.34246837 | AC31: =1 - AB31 -> 0.65753163 | AE31: =IF(AB31 > AC31, 1, 2) -> 2 | AF31: =(VALUE(IF(OR(AND(AE31=2, K31="SEDANG"), AND(AE31=1, K31="TIDAK SEHAT")), 1, 0)))*1 -> 0
... A35: 202208 | B35: 44779 | C35: 69 | D35: 101 | E35: 49 | F35: 19 | G35: 87 | H35: 29 | I35: 101 | J35: PM2,5 | K35: TIDAK SEHAT | L35: DKI4 | N35: =(C35 - MIN(C$2:C$99)) / (MAX(C$2:C$99) - MIN(C$2:C$99)) -> 0.72413793 | O35: =(D35-MIN(D$2:D$99))/(MAX(D$2:D$99)-MIN(D$2:D$99)) -> 0.55238095 | P35: =(E35-MIN(E$2:E$99))/(MAX(E$2:E$99)-MIN(E$2:E$99)) -> 0.33333333 | Q35: =(F35-MIN(F$2:F$99))/(MAX(F$2:F$99)-MIN(F$2:F$99)) -> 0.52631579 | R35: =(G35-MIN(G$2:G$99))/(MAX(G$2:G$99)-MIN(G$2:G$99)) -> 0.42682927 | S35: =(H35-MIN(H$2:H$99))/(MAX(H$2:H$99)-MIN(H$2:H$99)) -> 0.5 | T35: =SUM(N35:S35) -> 3.0629973 | V35: 0.35 | W35: =1 - V35 -> 0.65 | X35: =V35^2 * N35 -> 0.088706897 | Y35: =W35^2 * N35 -> 0.30594828 | Z35: =(N35-$N$102)^2 + (O35-$O$102)^2 + (P35-$P$102)^2 + (Q35-$Q$102)^2 + (R35-$R$102)^2 + (S35-$S$102)^2 -> 0.11148372 | AA35: =(N35-$N$103)^2+(O35-$O$103)^2+(P35-$P$103)^2+(Q35-$Q$103)^2+(R35-$R$103)^2+(S35-$S$103)^2 -> 0.047244086 | AB35: =(1/Z35) / ((1/Z35) + (1/AA35)) -> 0.29764216 | AC35: =1 - AB35 -> 0.70235784 | AE35: =IF(AB35 > AC35, 1, 2) -> 2 | AF35: =(VALUE(IF(OR(AND(AE35=2, K35="SEDANG"), AND(AE35=1, K35="TIDAK SEHAT")), 1, 0)))*1 -> 0
A36: 202208 | B36: 44778 | C36: 60 | D36: 82 | E36: 47 | F36: 17 | G36: 79 | H36: 26 | I36: 82 | J36: PM2,5 | K36: SEDANG | L36: DKI4 | N36: =(C36 - MIN(C$2:C$99)) / (MAX(C$2:C$99) - MIN(C$2:C$99)) -> 0.56896552 | O36: =(D36-MIN(D$2:D$99))/(MAX(D$2:D$99)-MIN(D$2:D$99)) -> 0.37142857 | P36: =(E36-MIN(E$2:E$99))/(MAX(E$2:E$99)-MIN(E$2:E$99)) -> 0.16666667 | Q36: =(F36-MIN(F$2:F$99))/(MAX(F$2:F$99)-MIN(F$2:F$99)) -> 0.42105263 | R36: =(G36-MIN(G$2:G$99))/(MAX(G$2:G$99)-MIN(G$2:G$99)) -> 0.37804878 | S36: =(H36-MIN(H$2:H$99))/(MAX(H$2:H$99)-MIN(H$2:H$99)) -> 0.40625 | T36: =SUM(N36:S36) -> 2.3124122 | V36: 0.26 | W36: =1 - V36 -> 0.74 | X36: =V36^2 * N36 -> 0.038462069 | Y36: =W36^2 * N36 -> 0.31156552 | Z36: =(N36-$N$102)^2+(O36-$O$102)^2+(P36-$P$102)^2+(Q36-$Q$102)^2+(R36-$R$102)^2+(S36-$S$102)^2 -> 0.1539887 | AA36: =(N36-$N$103)^2+(O36-$O$103)^2+(P36-$P$103)^2+(Q36-$Q$103)^2+(R36-$R$103)^2+(S36-$S$103)^2 -> 0.10078857 | AB36: =(1/Z36) / ((1/Z36) + (1/AA36)) -> 0.39559483 | AC36: =1 - AB36 -> 0.60440517 | AE36: =IF(AB36 > AC36, 1, 2) -> 2 | AF36: =(VALUE(IF(OR(AND(AE36=2, K36="SEDANG"), AND(AE36=1, K36="TIDAK SEHAT")), 1, 0)))*1 -> 1
A37: 202208 | B37: 44777 | C37: 69 | D37: 99 | E37: 48 | F37: 15 | G37: 82 | H37: 20 | I37: 99 | J37: PM2,5 | K37: SEDANG | L37: DKI4 | N37: =(C37 - MIN(C$2:C$99)) / (MAX(C$2:C$99) - MIN(C$2:C$99)) -> 0.72413793 | O37: =(D37-MIN(D$2:D$99))/(MAX(D$2:D$99)-MIN(D$2:D$99)) -> 0.53333333 | P37: =(E37-MIN(E$2:E$99))/(MAX(E$2:E$99)-MIN(E$2:E$99)) -> 0.25 | Q37: =(F37-MIN(F$2:F$99))/(MAX(F$2:F$99)-MIN(F$2:F$99)) -> 0.31578947 | R37: =(G37-MIN(G$2:G$99))/(MAX(G$2:G$99)-MIN(G$2:G$99)) -> 0.39634146 | S37: =(H37-MIN(H$2:H$99))/(MAX(H$2:H$99)-MIN(H$2:H$99)) -> 0.21875 | T37: =SUM(N37:S37) -> 2.4383522 | V37: 0.37 | W37: =1 - V37 -> 0.63 | X37: =V37^2 * N37 -> 0.099134483 | Y37: =W37^2 * N37 -> 0.28741034 | Z37: =(N37-$N$102)^2 + (O37-$O$102)^2 + (P37-$P$102)^2 + (Q37-$Q$102)^2 + (R37-$R$102)^2 + (S37-$S$102)^2 -> 0.24684946 | AA37: =(N37-$N$103)^2+(O37-$O$103)^2+(P37-$P$103)^2+(Q37-$Q$103)^2+(R37-$R$103)^2+(S37-$S$103)^2 -> 0.11338823 | AB37: =(1/Z37) / ((1/Z37) + (1/AA37)) -> 0.31475948 | AC37: =1 - AB37 -> 0.68524052 | AE37: =IF(AB37 > AC37, 1, 2) -> 2 | AF37: =(VALUE(IF(OR(AND(AE37=2, K37="SEDANG"), AND(AE37=1, K37="TIDAK SEHAT")), 1, 0)))*1 -> 1
A38: 202208 | B38: 44776 | C38: 82 | D38: 141 | E38: 51 | F38: 19 | G38: 129 | H38: 24 | I38: 141 | J38: PM2,5 | K38: TIDAK SEHAT | L38: DKI4 | N38: =(C38 - MIN(C$2:C$99)) / (MAX(C$2:C$99) - MIN(C$2:C$99)) -> 0.94827586 | O38: =(D38-MIN(D$2:D$99))/(MAX(D$2:D$99)-MIN(D$2:D$99)) -> 0.93333333 | P38: =(E38-MIN(E$2:E$99))/(MAX(E$2:E$99)-MIN(E$2:E$99)) -> 0.5 | Q38: =(F38-MIN(F$2:F$99))/(MAX(F$2:F$99)-MIN(F$2:F$99)) -> 0.52631579 | R38: =(G38-MIN(G$2:G$99))/(MAX(G$2:G$99)-MIN(G$2:G$99)) -> 0.68292683 | S38: =(H38-MIN(H$2:H$99))/(MAX(H$2:H$99)-MIN(H$2:H$99)) -> 0.34375 | T38: =SUM(N38:S38) -> 3.9346018 | V38: 0.38 | W38: =1 - V38 -> 0.62 | X38: =V38^2 * N38 -> 0.13693103 | Y38: =W38^2 * N38 -> 0.36451724 | Z38: =(N38-$N$102)^2 + (O38-$O$102)^2 + (P38-$P$102)^2 + (Q38-$Q$102)^2 + (R38-$R$102)^2 + (S38-$S$102)^2 -> 0.65803385 | AA38: =(N38-$N$103)^2+(O38-$O$103)^2+(P38-$P$103)^2+(Q38-$Q$103)^2+(R38-$R$103)^2+(S38-$S$103)^2 -> 0.44963965 | AB38: =(1/Z38) / ((1/Z38) + (1/AA38)) -> 0.40593158 | AC38: =1 - AB38 -> 0.59406842 | AE38: =IF(AB38 > AC38, 1, 2) -> 2 | AF38: =(VALUE(IF(OR(AND(AE38=2, K38="SEDANG"), AND(AE38=1, K38="TIDAK SEHAT")), 1, 0)))*1 -> 0
A39: 202208 | B39: 44775 | C39: 67 | D39: 113 | E39: 50 | F39: 15 | G39: 84 | H39: 28 | I39: 113 | J39: PM2,5 | K39: TIDAK SEHAT | L39: DKI4 | N39: =(C39 - MIN(C$2:C$99)) / (MAX(C$2:C$99) - MIN(C$2:C$99)) -> 0.68965517 | O39: =(D39-MIN(D$2:D$99))/(MAX(D$2:D$99)-MIN(D$2:D$99)) -> 0.66666667 | P39: =(E39-MIN(E$2:E$99))/(MAX(E$2:E$99)-MIN(E$2:E$99)) -> 0.41666667 | Q39: =(F39-MIN(F$2:F$99))/(MAX(F$2:F$99)-MIN(F$2:F$99)) -> 0.31578947 | R39: =(G39-MIN(G$2:G$99))/(MAX(G$2:G$99)-MIN(G$2:G$99)) -> 0.40853659 | S39: =(H39-MIN(H$2:H$99))/(MAX(H$2:H$99)-MIN(H$2:H$99)) -> 0.46875 | T39: =SUM(N39:S39) -> 2.9660646 | V39: 0.39 | W39: =1 - V39 -> 0.61 | X39: =V39^2 * N39 -> 0.10489655 | Y39: =W39^2 * N39 -> 0.25662069 | Z39: =(N39-$N$102)^2 + (O39-$O$102)^2 + (P39-$P$102)^2 + (Q39-$Q$102)^2 + (R39-$R$102)^2 + (S39-$S$102)^2 -> 0.13633467 | AA39: =(N39-$N$103)^2+(O39-$O$103)^2+(P39-$P$103)^2+(Q39-$Q$103)^2+(R39-$R$103)^2+(S39-$S$103)^2 -> 0.055055873 | AB39: =(1/Z39) / ((1/Z39) + (1/AA39)) -> 0.28766245 | AC39: =1 - AB39 -> 0.71233755 | AE39: =IF(AB39 > AC39, 1, 2) -> 2 | AF39: =(VALUE(IF(OR(AND(AE39=2, K39="SEDANG"), AND(AE39=1, K39="TIDAK SEHAT")), 1, 0)))*1 -> 0
A40: 202209 | B40: 44805 | C40: 83 | D40: 130 | E40: 51 | F40: 15 | G40: 42 | H40: 25 | I40: 130 | J40: PM2,5 | K40: TIDAK SEHAT | L40: DKI4 | N40: =(C40 - MIN(C$2:C$99)) / (MAX(C$2:C$99) - MIN(C$2:C$99)) -> 0.96551724 | O40: =(D40-MIN(D$2:D$99))/(MAX(D$2:D$99)-MIN(D$2:D$99)) -> 0.82857143 | P40: =(E40-MIN(E$2:E$99))/(MAX(E$2:E$99)-MIN(E$2:E$99)) -> 0.5 | Q40: =(F40-MIN(F$2:F$99))/(MAX(F$2:F$99)-MIN(F$2:F$99)) -> 0.31578947 | R40: =(G40-MIN(G$2:G$99))/(MAX(G$2:G$99)-MIN(G$2:G$99)) -> 0.15243902 | S40: =(H40-MIN(H$2:H$99))/(MAX(H$2:H$99)-MIN(H$2:H$99)) -> 0.375 | T40: =SUM(N40:S40) -> 3.1373172 | V40: 0.4 | W40: =1 - V40 -> 0.6 | X40: =V40^2 * N40 -> 0.15448276 | Y40: =W40^2 * N40 -> 0.34758621 | Z40: =(N40-$N$102)^2 + (O40-$O$102)^2 + (P40-$P$102)^2 + (Q40-$Q$102)^2 + (R40-$R$102)^2 + (S40-$S$102)^2 -> 0.34353742 | AA40: =(N40-$N$103)^2+(O40-$O$103)^2+(P40-$P$103)^2+(Q40-$Q$103)^2+(R40-$R$103)^2+(S40-$S$103)^2 -> 0.25082219 | AB40: =(1/Z40) / ((1/Z40) + (1/AA40)) -> 0.4220041 | AC40: =1 - AB40 -> 0.5779959 | AE40: =IF(AB40 > AC40, 1, 2) -> 2 | AF40: =(VALUE(IF(OR(AND(AE40=2, K40="SEDANG"), AND(AE40=1, K40="TIDAK SEHAT")), 1, 0)))*1 -> 0
A41: 202209 | B41: 44834 | C41: 71 | D41: 103 | E41: 51 | F41: 14 | G41: 45 | H41: 23 | I41: 103 | J41: PM2,5 | K41: TIDAK SEHAT | L41: DKI4 | N41: =(C41 - MIN(C$2:C$99)) / (MAX(C$2:C$99) - MIN(C$2:C$99)) -> 0.75862069 | O41: =(D41-MIN(D$2:D$99))/(MAX(D$2:D$99)-MIN(D$2:D$99)) -> 0.57142857 | P41: =(E41-MIN(E$2:E$99))/(MAX(E$2:E$99)-MIN(E$2:E$99)) -> 0.5 | Q41: =(F41-MIN(F$2:F$99))/(MAX(F$2:F$99)-MIN(F$2:F$99)) -> 0.26315789 | R41: =(G41-MIN(G$2:G$99))/(MAX(G$2:G$99)-MIN(G$2:G$99)) -> 0.17073171 | S41: =(H41-MIN(H$2:H$99))/(MAX(H$2:H$99)-MIN(H$2:H$99)) -> 0.3125 | T41: =SUM(N41:S41) -> 2.5764389 | V41: 0.41 | W41: =1 - V41 -> 0.59 | X41: =V41^2 * N41 -> 0.12752414 | Y41: =W41^2 * N41 -> 0.26407586 | Z41: =(N41-$N$102)^2 + (O41-$O$102)^2 + (P41-$P$102)^2 + (Q41-$Q$102)^2 + (R41-$R$102)^2 + (S41-$S$102)^2 -> 0.14242539 | AA41: =(N41-$N$103)^2+(O41-$O$103)^2+(P41-$P$103)^2+(Q41-$Q$103)^2+(R41-$R$103)^2+(S41-$S$103)^2 -> 0.08371592 | AB41: =(1/Z41) / ((1/Z41) + (1/AA41)) -> 0.37019295 | AC41: =1 - AB41 -> 0.62980705 | AE41: =IF(AB41 > AC41, 1, 2) -> 2 | AF41: =(VALUE(IF(OR(AND(AE41=2, K41="SEDANG"), AND(AE41=1, K41="TIDAK SEHAT")), 1, 0)))*1 -> 0
A42: 202209 | B42: 44833 | C42: 62 | D42: 100 | E42: 51 | F42: 14 | G42: 50 | H42: 21 | I42: 100 | J42: PM2,5 | K42: SEDANG | L42: DKI4 | N42: =(C42 - MIN(C$2:C$99)) / (MAX(C$2:C$99) - MIN(C$2:C$99)) -> 0.60344828 | O42: =(D42-MIN(D$2:D$99))/(MAX(D$2:D$99)-MIN(D$2:D$99)) -> 0.54285714 | P42: =(E42-MIN(E$2:E$99))/(MAX(E$2:E$99)-MIN(E$2:E$99)) -> 0.5 | Q42: =(F42-MIN(F$2:F$99))/(MAX(F$2:F$99)-MIN(F$2:F$99)) -> 0.26315789 | R42: =(G42-MIN(G$2:G$99))/(MAX(G$2:G$99)-MIN(G$2:G$99)) -> 0.20121951 | S42: =(H42-MIN(H$2:H$99))/(MAX(H$2:H$99)-MIN(H$2:H$99)) -> 0.25 | T42: =SUM(N42:S42) -> 2.3606828 | V42: 0.42 | W42: =1 - V42 -> 0.58 | X42: =V42^2 * N42 -> 0.10644828 | Y42: =W42^2 * N42 -> 0.203 | Z42: =(N42-$N$102)^2 + (O42-$O$102)^2 + (P42-$P$102)^2 + (Q42-$Q$102)^2 + (R42-$R$102)^2 + (S42-$S$102)^2 -> 0.13837388 | AA42: =(N42-$N$103)^2+(O42-$O$103)^2+(P42-$P$103)^2+(Q42-$Q$103)^2+(R42-$R$103)^2+(S42-$S$103)^2 -> 0.082565454 | AB42: =(1/Z42) / ((1/Z42) + (1/AA42)) -> 0.37370192 | AC42: =1 - AB42 -> 0.62629808 | AE42: =IF(AB42 > AC42, 1, 2) -> 2 | AF42: =(VALUE(IF(OR(AND(AE42=2, K42="SEDANG"), AND(AE42=1, K42="TIDAK SEHAT")), 1, 0)))*1 -> 1
A43: 202209 | B43: 44832 | C43: 62 | D43: 92 | E43: 51 | F43: 13 | G43: 55 | H43: 24 | I43: 92 | J43: PM2,5 | K43: SEDANG | L43: DKI4 | N43: =(C43 - MIN(C$2:C$99)) / (MAX(C$2:C$99) - MIN(C$2:C$99)) -> 0.60344828 | O43: =(D43-MIN(D$2:D$99))/(MAX(D$2:D$99)-MIN(D$2:D$99)) -> 0.46666667 | P43: =(E43-MIN(E$2:E$99))/(MAX(E$2:E$99)-MIN(E$2:E$99)) -> 0.5 | Q43: =(F43-MIN(F$2:F$99))/(MAX(F$2:F$99)-MIN(F$2:F$99)) -> 0.21052632 | R43: =(G43-MIN(G$2:G$99))/(MAX(G$2:G$99)-MIN(G$2:G$99)) -> 0.23170732 | S43: =(H43-MIN(H$2:H$99))/(MAX(H$2:H$99)-MIN(H$2:H$99)) -> 0.34375 | T43: =SUM(N43:S43) -> 2.3560986 | V43: 0.43 | W43: =1 - V43 -> 0.57 | X43: =V43^2 * N43 -> 0.11157759 | Y43: =W43^2 * N43 -> 0.19606034 | Z43: =(N43-$N$102)^2 + (O43-$O$102)^2 + (P43-$P$102)^2 + (Q43-$Q$102)^2 + (R43-$R$102)^2 + (S43-$S$102)^2 -> 0.10876666 | AA43: =(N43-$N$103)^2+(O43-$O$103)^2+(P43-$P$103)^2+(Q43-$Q$103)^2+(R43-$R$103)^2+(S43-$S$103)^2 -> 0.071506062 | AB43: =(1/Z43) / ((1/Z43) + (1/AA43)) -> 0.39665492 | AC43: =1 - AB43 -> 0.60334508 | AE43: =IF(AB43 > AC43, 1, 2) -> 2 | AF43: =(VALUE(IF(OR(AND(AE43=2, K43="SEDANG"), AND(AE43=1, K43="TIDAK SEHAT")), 1, 0)))*1 -> 1
...

Sheet Sheet2
A1: periode_data | B1: tanggal | C1: pm_10 | D1: pm_duakomalima | E1: so2 | F1: co | G1: o3 | H1: no2 | I1: max | J1: critical | K1: categori | L1: lokasi_spku | N1: U1 | O1: U2 | P1: U1^2 | Q1: U2^2 | R1: Jarak D1 | S1: Jarak D2 | T1: F.Objektif | V1: (u1)^m | W1: (u2)^m | X1: (u1)^m.X | Y1: (u2)^m.X | Z1: d1^2 | AA1: d2^2 | AB1: u1 Baru | AC1: u2 Baru | AD1: Selisih | AF1: Label | AG1: Cek Kecocokan
A2: 202212 | B2: 44926.625 | C2: 54 | D2: 73 | E2: 56 | F2: 24 | G2: 23 | H2: 24 | I2: 73 | J2: PM2,5 | K2: SEDANG | L2: DKI4 | N2: =(C2-MIN(C$2:C$99))/(MAX(C$2:C$99)-MIN(C$2:C$99)) -> 0.46551724 | O2: =(D2-MIN(D$2:D$99))/(MAX(D$2:D$99)-MIN(D$2:D$99)) -> 0.28571429 | P2: =(E2-MIN(E$2:E$99))/(MAX(E$2:E$99)-MIN(E$2:E$99)) -> 0.91666667 | Q2: =(F2-MIN(F$2:F$99))/(MAX(F$2:F$99)-MIN(F$2:F$99)) -> 0.78947368 | R2: =(G2-MIN(G$2:G$99))/(MAX(G$2:G$99)-MIN(G$2:G$99)) -> 0.036585366 | S2: =(H2-MIN(H$2:H$99))/(MAX(H$2:H$99)-MIN(H$2:H$99)) -> 0.34375 | T2: =SUM(N2:S2) -> 2.8377072 | V2: =Sheet1!AB2^2 -> 0.31005271 | W2: =Sheet1!AC2^2 -> 0.19640517 | X2: =V2 * C2 -> 16.742846 | Y2: =W2 * N2 -> 0.091429994 | Z2: =(N2-N$102)^2 + (O2-O$102)^2 + (P2-P$102)^2 + (Q2-Q$102)^2 + (R2-R$102)^2 + (S2-S$102)^2 -> 0.39387293 | AA2: =(N2-N$103)^2 + (O2-O$103)^2 + (P2-P$103)^2 + (Q2-Q$103)^2 + (R2-R$103)^2 + (S2-S$103)^2 -> 1.881388 | AB2: =(1/Z2) / ((1/Z2) + (1/AA2)) -> 0.82688889 | AC2: =1 - AB2 -> 0.17311111 | AD2: =ABS(AB2 - N2) -> 0.36137165 | AF2: =IF(AB3 > AC3, 1, 2) -> 1 | AG2: =IF(OR(AND(AF3=1, K3="SEDANG"), AND(AF3=2, K3="TIDAK SEHAT")), 1, 0) -> 1
A3: 202212 | B3: 44925 | C3: 40 | D3: 64 | E3: 57 | F3: 21 | G3: 17 | H3: 24 | I3: 64 | J3: PM2,5 | K3: SEDANG | L3: DKI4 | N3: =(C3-MIN(C$2:C$99))/(MAX(C$2:C$99)-MIN(C$2:C$99)) -> 0.22413793 | O3: =(D3-MIN(D$2:D$99))/(MAX(D$2:D$99)-MIN(D$2:D$99)) -> 0.2 | P3: =(E3-MIN(E$2:E$99))/(MAX(E$2:E$99)-MIN(E$2:E$99)) -> 1 | Q3: =(F3-MIN(F$2:F$99))/(MAX(F$2:F$99)-MIN(F$2:F$99)) -> 0.63157895 | R3: =(G3-MIN(G$2:G$99))/(MAX(G$2:G$99)-MIN(G$2:G$99)) -> 0 | S3: =(H3-MIN(H$2:H$99))/(MAX(H$2:H$99)-MIN(H$2:H$99)) -> 0.34375 | T3: =SUM(N3:S3) -> 2.3994669 | V3: =Sheet1!AB3^2 -> 0.31072358 | W3: =Sheet1!AC3^2 -> 0.19587188 | X3: =V3 * C3 -> 12.428943 | Y3: =W3 * N3 -> 0.043902317 | Z3: =(N3-N$102)^2 + (O3-O$102)^2 + (P3-P$102)^2 + (Q3-Q$102)^2 + (R3-R$102)^2 + (S3-S$102)^2 -> 0.55702828 | AA3: =(N3-N$103)^2 + (O3-O$103)^2 + (P3-P$103)^2 + (Q3-Q$103)^2 + (R3-R$103)^2 + (S3-S$103)^2 -> 1.6072938 | AB3: =(1/Z3) / ((1/Z3) + (1/AA3)) -> 0.74263153 | AC3: =1 - AB3 -> 0.25736847 | AD3: =ABS(AB3 - N3) -> 0.51849359 | AF3: =IF(AB4 > AC4, 1, 2) -> 1 | AG3: =IF(OR(AND(AF4=1, K4="SEDANG"), AND(AF4=2, K4="TIDAK SEHAT")), 1, 0) -> 0
A4: 202207 | B4: 44748 | C4: 75 | D4: 129 | E4: 45 | F4: 25 | G4: 71 | H4: 26 | I4: 129 | J4: PM2,5 | K4: TIDAK SEHAT | L4: DKI4 | N4: =(C4-MIN(C$2:C$99))/(MAX(C$2:C$99)-MIN(C$2:C$99)) -> 0.82758621 | O4: =(D4-MIN(D$2:D$99))/(MAX(D$2:D$99)-MIN(D$2:D$99)) -> 0.81904762 | P4: =(E4-MIN(E$2:E$99))/(MAX(E$2:E$99)-MIN(E$2:E$99)) -> 0 | Q4: =(F4-MIN(F$2:F$99))/(MAX(F$2:F$99)-MIN(F$2:F$99)) -> 0.84210526 | R4: =(G4-MIN(G$2:G$99))/(MAX(G$2:G$99)-MIN(G$2:G$99)) -> 0.32926829 | S4: =(H4-MIN(H$2:H$99))/(MAX(H$2:H$99)-MIN(H$2:H$99)) -> 0.40625 | T4: =SUM(N4:S4) -> 3.2242574 | V4: =Sheet1!AB4^2 -> 0.2007635 | W4: =Sheet1!AC4^2 -> 0.3046307 | X4: =V4 * C4 -> 15.057262 | Y4: =W4 * N4 -> 0.25210816 | Z4: =(N4-N$102)^2 + (O4-O$102)^2 + (P4-P$102)^2 + (Q4-Q$102)^2 + (R4-R$102)^2 + (S4-S$102)^2 -> 0.63491724 | AA4: =(N4-N$103)^2 + (O4-O$103)^2 + (P4-P$103)^2 + (Q4-Q$103)^2 + (R4-R$103)^2 + (S4-S$103)^2 -> 2.3383359 | AB4: =(1/Z4) / ((1/Z4) + (1/AA4)) -> 0.78645705 | AC4: =1 - AB4 -> 0.21354295 | AD4: =ABS(AB4 - N4) -> 0.041129156 | AF4: =IF(AB5 > AC5, 1, 2) -> 1 | AG4: =IF(OR(AND(AF5=1, K5="SEDANG"), AND(AF5=2, K5="TIDAK SEHAT")), 1, 0) -> 1
A5: 202207 | B5: 44747 | C5: 66 | D5: 110 | E5: 47 | F5: 16 | G5: 61 | H5: 23 | I5: 110 | J5: PM2,5 | K5: TIDAK SEHAT | L5: DKI4 | N5: =(C5-MIN(C$2:C$99))/(MAX(C$2:C$99)-MIN(C$2:C$99)) -> 0.67241379 | O5: =(D5-MIN(D$2:D$99))/(MAX(D$2:D$99)-MIN(D$2:D$99)) -> 0.63809524 | P5: =(E5-MIN(E$2:E$99))/(MAX(E$2:E$99)-MIN(E$2:E$99)) -> 0.16666667 | Q5: =(F5-MIN(F$2:F$99))/(MAX(F$2:F$99)-MIN(F$2:F$99)) -> 0.36842105 | R5: =(G5-MIN(G$2:G$99))/(MAX(G$2:G$99)-MIN(G$2:G$99)) -> 0.26829268 | S5: =(H5-MIN(H$2:H$99))/(MAX(H$2:H$99)-MIN(H$2:H$99)) -> 0.3125 | T5: =SUM(N5:S5) -> 2.4263894 | V5: =Sheet1!AB5^2 -> 0.12054973 | W5: =Sheet1!AC5^2 -> 0.42614429 | X5: =V5 * C5 -> 7.9562822 | Y5: =W5 * N5 -> 0.2865453 | Z5: =(N5-N$102)^2 + (O5-O$102)^2 + (P5-P$102)^2 + (Q5-Q$102)^2 + (R5-R$102)^2 + (S5-S$102)^2 -> 0.26629549 | AA5: =(N5-N$103)^2 + (O5-O$103)^2 + (P5-P$103)^2 + (Q5-Q$103)^2 + (R5-R$103)^2 + (S5-S$103)^2 -> 1.1924549 | AB5: =(1/Z5) / ((1/Z5) + (1/AA5)) -> 0.81744958 | AC5: =1 - AB5 -> 0.18255042 | AD5: =ABS(AB5 - N5) -> 0.14503579 | AF5: =IF(AB6 > AC6, 1, 2) -> 2 | AG5: =IF(OR(AND(AF6=1, K6="SEDANG"), AND(AF6=2, K6="TIDAK SEHAT")), 1, 0) -> 1
A6: 202207 | B6: 44746 | C6: 56 | D6: 78 | E6: 49 | F6: 11 | G6: 60 | H6: 13 | I6: 78 | J6: PM2,5 | K6: SEDANG | L6: DKI4 | N6: =(C6-MIN(C$2:C$99))/(MAX(C$2:C$99)-MIN(C$2:C$99)) -> 0.5 | O6: =(D6-MIN(D$2:D$99))/(MAX(D$2:D$99)-MIN(D$2:D$99)) -> 0.33333333 | P6: =(E6-MIN(E$2:E$99))/(MAX(E$2:E$99)-MIN(E$2:E$99)) -> 0.33333333 | Q6: =(F6-MIN(F$2:F$99))/(MAX(F$2:F$99)-MIN(F$2:F$99)) -> 0.10526316 | R6: =(G6-MIN(G$2:G$99))/(MAX(G$2:G$99)-MIN(G$2:G$99)) -> 0.26219512 | S6: =(H6-MIN(H$2:H$99))/(MAX(H$2:H$99)-MIN(H$2:H$99)) -> 0 | T6: =SUM(N6:S6) -> 1.5341249 | V6: =Sheet1!AB6^2 -> 0.1899785 | W6: =Sheet1!AC6^2 -> 0.31824803 | X6: =V6 * C6 -> 10.638796 | Y6: =W6 * N6 -> 0.15912402 | Z6: =(N6-N$102)^2 + (O6-O$102)^2 + (P6-P$102)^2 + (Q6-Q$102)^2 + (R6-R$102)^2 + (S6-S$102)^2 -> 0.56570796 | AA6: =(N6-N$103)^2 + (O6-O$103)^2 + (P6-P$103)^2 + (Q6-Q$103)^2 + (R6-R$103)^2 + (S6-S$103)^2 -> 0.55204884 | AB6: =(1/Z6) / ((1/Z6) + (1/AA6)) -> 0.49388994 | AC6: =1 - AB6 -> 0.50611006 | AD6: =ABS(AB6 - N6) -> 0.0061100607 | AF6: =IF(AB7 > AC7, 1, 2) -> 1 | AG6: =IF(OR(AND(AF7=1, K7="SEDANG"), AND(AF7=2, K7="TIDAK SEHAT")), 1, 0) -> 0
A7: 202207 | B7: 44745 | C7: 78 | D7: 126 | E7: 48 | F7: 17 | G7: 126 | H7: 25 | I7: 126 | J7: PM2,5 | K7: TIDAK SEHAT | L7: DKI2 | N7: =(C7-MIN(C$2:C$99))/(MAX(C$2:C$99)-MIN(C$2:C$99)) -> 0.87931034 | O7: =(D7-MIN(D$2:D$99))/(MAX(D$2:D$99)-MIN(D$2:D$99)) -> 0.79047619 | P7: =(E7-MIN(E$2:E$99))/(MAX(E$2:E$99)-MIN(E$2:E$99)) -> 0.25 | Q7: =(F7-MIN(F$2:F$99))/(MAX(F$2:F$99)-MIN(F$2:F$99)) -> 0.42105263 | R7: =(G7-MIN(G$2:G$99))/(MAX(G$2:G$99)-MIN(G$2:G$99)) -> 0.66463415 | S7: =(H7-MIN(H$2:H$99))/(MAX(H$2:H$99)-MIN(H$2:H$99)) -> 0.375 | T7: =SUM(N7:S7) -> 3.3804733 | V7: =Sheet1!AB7^2 -> 0.14328608 | W7: =Sheet1!AC7^2 -> 0.38622312 | X7: =V7 * C7 -> 11.176314 | Y7: =W7 * N7 -> 0.33960999 | Z7: =(N7-N$102)^2 + (O7-O$102)^2 + (P7-P$102)^2 + (Q7-Q$102)^2 + (R7-R$102)^2 + (S7-S$102)^2 -> 0.58493189 | AA7: =(N7-N$103)^2 + (O7-O$103)^2 + (P7-P$103)^2 + (Q7-Q$103)^2 + (R7-R$103)^2 + (S7-S$103)^2 -> 2.2201882 | AB7: =(1/Z7) / ((1/Z7) + (1/AA7)) -> 0.79147706 | AC7: =1 - AB7 -> 0.20852294 | AD7: =ABS(AB7 - N7) -> 0.087833288 | AF7: =IF(AB8 > AC8, 1, 2) -> 1 | AG7: =IF(OR(AND(AF8=1, K8="SEDANG"), AND(AF8=2, K8="TIDAK SEHAT")), 1, 0) -> 0
A8: 202207 | B8: 44744 | C8: 81 | D8: 137 | E8: 47 | F8: 18 | G8: 106 | H8: 29 | I8: 137 | J8: PM2,5 | K8: TIDAK SEHAT | L8: DKI4 | N8: =(C8-MIN(C$2:C$99))/(MAX(C$2:C$99)-MIN(C$2:C$99)) -> 0.93103448 | O8: =(D8-MIN(D$2:D$99))/(MAX(D$2:D$99)-MIN(D$2:D$99)) -> 0.8952381 | P8: =(E8-MIN(E$2:E$99))/(MAX(E$2:E$99)-MIN(E$2:E$99)) -> 0.16666667 | Q8: =(F8-MIN(F$2:F$99))/(MAX(F$2:F$99)-MIN(F$2:F$99)) -> 0.47368421 | R8: =(G8-MIN(G$2:G$99))/(MAX(G$2:G$99)-MIN(G$2:G$99)) -> 0.54268293 | S8: =(H8-MIN(H$2:H$99))/(MAX(H$2:H$99)-MIN(H$2:H$99)) -> 0.5 | T8: =SUM(N8:S8) -> 3.5093064 | V8: =Sheet1!AB8^2 -> 0.16578727 | W8: =Sheet1!AC8^2 -> 0.35144762 | X8: =V8 * C8 -> 13.428769 | Y8: =W8 * N8 -> 0.32720985 | Z8: =(N8-N$102)^2 + (O8-O$102)^2 + (P8-P$102)^2 + (Q8-Q$102)^2 + (R8-R$102)^2 + (S8-S$102)^2 -> 0.59893359 | AA8: =(N8-N$103)^2 + (O8-O$103)^2 + (P8-P$103)^2 + (Q8-Q$103)^2 + (R8-R$103)^2 + (S8-S$103)^2 -> 2.4649357 | AB8: =(1/Z8) / ((1/Z8) + (1/AA8)) -> 0.80451725 | AC8: =1 - AB8 -> 0.19548275 | AD8: =ABS(AB8 - N8) -> 0.12651723 | AF8: =IF(AB9 > AC9, 1, 2) -> 1 | AG8: =IF(OR(AND(AF9=1, K9="SEDANG"), AND(AF9=2, K9="TIDAK SEHAT")), 1, 0) -> 0
A9: 202208 | B9: 44774 | C9: 68 | D9: 109 | E9: 50 | F9: 12 | G9: 91 | H9: 19 | I9: 109 | J9: PM2,5 | K9: TIDAK SEHAT | L9: DKI4 | N9: =(C9-MIN(C$2:C$99))/(MAX(C$2:C$99)-MIN(C$2:C$99)) -> 0.70689655 | O9: =(D9-MIN(D$2:D$99))/(MAX(D$2:D$99)-MIN(D$2:D$99)) -> 0.62857143 | P9: =(E9-MIN(E$2:E$99))/(MAX(E$2:E$99)-MIN(E$2:E$99)) -> 0.41666667 | Q9: =(F9-MIN(F$2:F$99))/(MAX(F$2:F$99)-MIN(F$2:F$99)) -> 0.15789474 | R9: =(G9-MIN(G$2:G$99))/(MAX(G$2:G$99)-MIN(G$2:G$99)) -> 0.45121951 | S9: =(H9-MIN(H$2:H$99))/(MAX(H$2:H$99)-MIN(H$2:H$99)) -> 0.1875 | T9: =SUM(N9:S9) -> 2.5487489 | V9: =Sheet1!AB9^2 -> 0.1231701 | W9: =Sheet1!AC9^2 -> 0.42125814 | X9: =V9 * C9 -> 8.3755667 | Y9: =W9 * N9 -> 0.29778593 | Z9: =(N9-N$102)^2 + (O9-O$102)^2 + (P9-P$102)^2 + (Q9-Q$102)^2 + (R9-R$102)^2 + (S9-S$102)^2 -> 0.43377933 | AA9: =(N9-N$103)^2 + (O9-O$103)^2 + (P9-P$103)^2 + (Q9-Q$103)^2 + (R9-R$103)^2 + (S9-S$103)^2 -> 1.3321019 | AB9: =(1/Z9) / ((1/Z9) + (1/AA9)) -> 0.75435532 | AC9: =1 - AB9 -> 0.24564468 | AD9: =ABS(AB9 - N9) -> 0.047458772 | AF9: =IF(AB10 > AC10, 1, 2) -> 1 | AG9: =IF(OR(AND(AF10=1, K10="SEDANG"), AND(AF10=2, K10="TIDAK SEHAT")), 1, 0) -> 0
A10: 202208 | B10: 44804 | C10: 85 | D10: 148 | E10: 51 | F10: 25 | G10: 74 | H10: 37 | I10: 148 | J10: PM2,5 | K10: TIDAK SEHAT | L10: DKI4 | N10: =(C10-MIN(C$2:C$99))/(MAX(C$2:C$99)-MIN(C$2:C$99)) -> 1 | O10: =(D10-MIN(D$2:D$99))/(MAX(D$2:D$99)-MIN(D$2:D$99)) -> 1 | P10: =(E10-MIN(E$2:E$99))/(MAX(E$2:E$99)-MIN(E$2:E$99)) -> 0.5 | Q10: =(F10-MIN(F$2:F$99))/(MAX(F$2:F$99)-MIN(F$2:F$99)) -> 0.84210526 | R10: =(G10-MIN(G$2:G$99))/(MAX(G$2:G$99)-MIN(G$2:G$99)) -> 0.34756098 | S10: =(H10-MIN(H$2:H$99))/(MAX(H$2:H$99)-MIN(H$2:H$99)) -> 0.75 | T10: =SUM(N10:S10) -> 4.4396662 | V10: =Sheet1!AB10^2 -> 0.23245122 | W10: =Sheet1!AC10^2 -> 0.26818732 | X10: =V10 * C10 -> 19.758354 | Y10: =W10 * N10 -> 0.26818732 | Z10: =(N10-N$102)^2 + (O10-O$102)^2 + (P10-P$102)^2 + (Q10-Q$102)^2 + (R10-R$102)^2 + (S10-S$102)^2 -> 0.68518416 | AA10: =(N10-N$103)^2 + (O10-O$103)^2 + (P10-P$103)^2 + (Q10-Q$103)^2 + (R10-R$103)^2 + (S10-S$103)^2 -> 3.6424399 | AB10: =(1/Z10) / ((1/Z10) + (1/AA10)) -> 0.84167198 | AC10: =1 - AB10 -> 0.15832802 | AD10: =ABS(AB10 - N10) -> 0.15832802 | AF10: =IF(AB11 > AC11, 1, 2) -> 1 | AG10: =IF(OR(AND(AF11=1, K11="SEDANG"), AND(AF11=2, K11="TIDAK SEHAT")), 1, 0) -> 1
A11: 202208 | B11: 44803 | C11: 59 | D11: 84 | E11: 50 | F11: 15 | G11: 56 | H11: 29 | I11: 84 | J11: PM2,5 | K11: SEDANG | L11: DKI4 | N11: =(C11-MIN(C$2:C$99))/(MAX(C$2:C$99)-MIN(C$2:C$99)) -> 0.55172414 | O11: =(D11-MIN(D$2:D$99))/(MAX(D$2:D$99)-MIN(D$2:D$99)) -> 0.39047619 | P11: =(E11-MIN(E$2:E$99))/(MAX(E$2:E$99)-MIN(E$2:E$99)) -> 0.41666667 | Q11: =(F11-MIN(F$2:F$99))/(MAX(F$2:F$99)-MIN(F$2:F$99)) -> 0.31578947 | R11: =(G11-MIN(G$2:G$99))/(MAX(G$2:G$99)-MIN(G$2:G$99)) -> 0.23780488 | S11: =(H11-MIN(H$2:H$99))/(MAX(H$2:H$99)-MIN(H$2:H$99)) -> 0.5 | T11: =SUM(N11:S11) -> 2.4124613 | V11: =Sheet1!AB11^2 -> 0.3129015 | W11: =Sheet1!AC11^2 -> 0.19414952 | X11: =V11 * C11 -> 18.461188 | Y11: =W11 * N11 -> 0.10711698 | Z11: =(N11-N$102)^2 + (O11-O$102)^2 + (P11-P$102)^2 + (Q11-Q$102)^2 + (R11-R$102)^2 + (S11-S$102)^2 -> 0.054626965 | AA11: =(N11-N$103)^2 + (O11-O$103)^2 + (P11-P$103)^2 + (Q11-Q$103)^2 + (R11-R$103)^2 + (S11-S$103)^2 -> 1.0367564 | AB11: =(1/Z11) / ((1/Z11) + (1/AA11)) -> 0.94994704 | AC11: =1 - AB11 -> 0.050052956 | AD11: =ABS(AB11 - N11) -> 0.39822291 | AF11: =IF(AB12 > AC12, 1, 2) -> 1 | AG11: =IF(OR(AND(AF12=1, K12="SEDANG"), AND(AF12=2, K12="TIDAK SEHAT")), 1, 0) -> 1
A12: 202208 | B12: 44802 | C12: 58 | D12: 82 | E12: 49 | F12: 16 | G12: 55 | H12: 29 | I12: 82 | J12: PM2,5 | K12: SEDANG | L12: DKI4 | N12: =(C12-MIN(C$2:C$99))/(MAX(C$2:C$99)-MIN(C$2:C$99)) -> 0.53448276 | O12: =(D12-MIN(D$2:D$99))/(MAX(D$2:D$99)-MIN(D$2:D$99)) -> 0.37142857 | P12: =(E12-MIN(E$2:E$99))/(MAX(E$2:E$99)-MIN(E$2:E$99)) -> 0.33333333 | Q12: =(F12-MIN(F$2:F$99))/(MAX(F$2:F$99)-MIN(F$2:F$99)) -> 0.36842105 | R12: =(G12-MIN(G$2:G$99))/(MAX(G$2:G$99)-MIN(G$2:G$99)) -> 0.23170732 | S12: =(H12-MIN(H$2:H$99))/(MAX(H$2:H$99)-MIN(H$2:H$99)) -> 0.5 | T12: =SUM(N12:S12) -> 2.339373 | V12: =Sheet1!AB12^2 -> 0.31672329 | W12: =Sheet1!AC12^2 -> 0.19115981 | X12: =V12 * C12 -> 18.369951 | Y12: =W12 * N12 -> 0.10217162 | Z12: =(N12-N$102)^2 + (O12-O$102)^2 + (P12-P$102)^2 + (Q12-Q$102)^2 + (R12-R$102)^2 + (S12-S$102)^2 -> 0.057548171 | AA12: =(N12-N$103)^2 + (O12-O$103)^2 + (P12-P$103)^2 + (Q12-Q$103)^2 + (R12-R$103)^2 + (S12-S$103)^2 -> 0.97416447 | AB12: =(1/Z12) / ((1/Z12) + (1/AA12)) -> 0.94422074 | AC12: =1 - AB12 -> 0.055779264 | AD12: =ABS(AB12 - N12) -> 0.40973798 | AF12: =IF(AB13 > AC13, 1, 2) -> 1 | AG12: =IF(OR(AND(AF13=1, K13="SEDANG"), AND(AF13=2, K13="TIDAK SEHAT")), 1, 0) -> 1
A13: 202208 | B13: 44801 | C13: 64 | D13: 85 | E13: 49 | F13: 17 | G13: 56 | H13: 30 | I13: 85 | J13: PM2,5 | K13: SEDANG | L13: DKI5 | N13: =(C13-MIN(C$2:C$99))/(MAX(C$2:C$99)-MIN(C$2:C$99)) -> 0.63793103 | O13: =(D13-MIN(D$2:D$99))/(MAX(D$2:D$99)-MIN(D$2:D$99)) -> 0.4 | P13: =(E13-MIN(E$2:E$99))/(MAX(E$2:E$99)-MIN(E$2:E$99)) -> 0.33333333 | Q13: =(F13-MIN(F$2:F$99))/(MAX(F$2:F$99)-MIN(F$2:F$99)) -> 0.42105263 | R13: =(G13-MIN(G$2:G$99))/(MAX(G$2:G$99)-MIN(G$2:G$99)) -> 0.23780488 | S13: =(H13-MIN(H$2:H$99))/(MAX(H$2:H$99)-MIN(H$2:H$99)) -> 0.53125 | T13: =SUM(N13:S13) -> 2.5613719 | V13: =Sheet1!AB13^2 -> 0.28103923 | W13: =Sheet1!AC13^2 -> 0.22077657 | X13: =V13 * C13 -> 17.98651 | Y13: =W13 * N13 -> 0.14084022 | Z13: =(N13-N$102)^2 + (O13-O$102)^2 + (P13-P$102)^2 + (Q13-Q$102)^2 + (R13-R$102)^2 + (S13-S$102)^2 -> 0.043139763 | AA13: =(N13-N$103)^2 + (O13-O$103)^2 + (P13-P$103)^2 + (Q13-Q$103)^2 + (R13-R$103)^2 + (S13-S$103)^2 -> 1.1941302 | AB13: =(1/Z13) / ((1/Z13) + (1/AA13)) -> 0.9651331 | AC13: =1 - AB13 -> 0.034866897 | AD13: =ABS(AB13 - N13) -> 0.32720207 | AF13: =IF(AB14 > AC14, 1, 2) -> 1 | AG13: =IF(OR(AND(AF14=1, K14="SEDANG"), AND(AF14=2, K14="TIDAK SEHAT")), 1, 0) -> 0
